2020-09-18 15:19:22,343 - discord.client - logging in using static token
2020-09-18 15:19:28,834 - discord.gateway - Created websocket connected to wss://gateway.discord.gg?encoding=json&v=6&compress=zlib-stream
2020-09-18 15:19:28,837 - discord.gateway - Shard ID None has sent the IDENTIFY payload.
2020-09-18 15:19:29,837 - discord.gateway - Shard ID None has connected to Gateway: ["gateway-prd-main-08jl",{"micros":82594,"calls":["discord-sessions-prd-2-79",{"micros":77703,"calls":["start_session",{"micros":34414,"calls":["api-prd-main-mbqv",{"micros":30592,"calls":["get_user",{"micros":2889},"add_authorized_ip",{"micros":1486},"get_guilds",{"micros":5325},"coros_wait",{"micros":2}]}]},"guilds_connect",{"micros":3,"calls":[]},"presence_connect",{"micros":31314,"calls":[]}]}]}] (Session ID: bcf3d431ef72c581caa2d5e585d3a736).
2020-09-18 15:19:29,855 - bot.bot - Connection to Discord established.
2020-09-18 15:19:31,881 - console - Successfully logged in as gambling bot ID:729824279990108222 	d.py version: 1.3.4 	Further logging output will go to log file..
2020-09-18 15:19:31,958 - console - loaded bot.cogs.games
2020-09-18 15:19:34,696 - discord.state - Processed a chunk for 1000 members in guild ID 577192344529404154.
2020-09-18 15:19:34,721 - discord.state - Processed a chunk for 1000 members in guild ID 577192344529404154.
2020-09-18 15:19:34,724 - discord.state - Processed a chunk for 157 members in guild ID 577192344529404154.
2020-09-18 15:19:35,722 - discord.client - Received signal to terminate bot and event loop.
2020-09-18 15:19:35,722 - discord.client - Cleaning up tasks.
2020-09-18 15:19:35,722 - discord.client - Cleaning up after 6 tasks.
2020-09-18 15:19:35,911 - discord.client - Closing the event loop.
2020-09-18 15:19:52,254 - discord.client - logging in using static token
2020-09-18 15:19:55,757 - discord.gateway - Created websocket connected to wss://gateway.discord.gg?encoding=json&v=6&compress=zlib-stream
2020-09-18 15:19:55,758 - discord.gateway - Shard ID None has sent the IDENTIFY payload.
2020-09-18 15:19:57,737 - discord.gateway - Shard ID None has connected to Gateway: ["gateway-prd-main-l5rc",{"micros":71433,"calls":["discord-sessions-prd-1-1",{"micros":70544,"calls":["start_session",{"micros":42688,"calls":["api-prd-main-8hsd",{"micros":40672,"calls":["get_user",{"micros":2494},"add_authorized_ip",{"micros":2143},"get_guilds",{"micros":3398},"coros_wait",{"micros":0}]}]},"guilds_connect",{"micros":3,"calls":[]},"presence_connect",{"micros":1,"calls":[]}]}]}] (Session ID: 22dcec8cf587a519f52d959527afe355).
2020-09-18 15:19:57,755 - bot.bot - Connection to Discord established.
2020-09-18 15:19:59,761 - console - Successfully logged in as gambling bot ID:729824279990108222 	d.py version: 1.3.4 	Further logging output will go to log file..
2020-09-18 15:19:59,786 - console - loaded bot.cogs.games
2020-09-18 15:19:59,854 - console - loaded bot.cogs.other
2020-09-18 15:20:02,858 - discord.state - Processed a chunk for 1000 members in guild ID 577192344529404154.
2020-09-18 15:20:02,945 - discord.state - Somehow timed out waiting for chunks.
2020-09-18 15:20:03,431 - discord.state - Processed a chunk for 1000 members in guild ID 577192344529404154.
2020-09-18 15:20:03,436 - discord.state - Processed a chunk for 157 members in guild ID 577192344529404154.
2020-09-18 15:20:04,825 - bot.bot - on_ready event error exception!
Traceback (most recent call last):
  File "C:\Users\Vaishnav\.virtualenvs\Tortoise-BOT-NdGTmAqy\lib\site-packages\discord\client.py", line 312, in _run_event
    await coro(*args, **kwargs)
  File "C:\Users\Vaishnav\Projects\Tortoise-BOT\bot\bot.py", line 43, in on_ready
    await self.on_first_ready()
  File "C:\Users\Vaishnav\Projects\Tortoise-BOT\bot\bot.py", line 49, in on_first_ready
    await self.reload_tortoise_meta_cache()
  File "C:\Users\Vaishnav\Projects\Tortoise-BOT\bot\bot.py", line 55, in reload_tortoise_meta_cache
    self.tortoise_meta_cache = await self.api_client.get_server_meta()
  File "C:\Users\Vaishnav\Projects\Tortoise-BOT\bot\api_client.py", line 128, in get_server_meta
    return await self.get(f"server/meta/{guild_id}/")
  File "C:\Users\Vaishnav\Projects\Tortoise-BOT\bot\api_client.py", line 62, in get
    await self.raise_for_status(resp)
  File "C:\Users\Vaishnav\Projects\Tortoise-BOT\bot\api_client.py", line 55, in raise_for_status
    raise ResponseCodeError(response=response, response_json=response_json)
bot.api_client.ResponseCodeError: Status: 401 Response: {'detail': 'Invalid token.'}

2020-09-18 15:20:05,489 - asyncio - _ClientEventTask exception was never retrieved
future: <ClientEventTask state=finished event=on_ready coro=<bound method Bot.on_ready of <bot.bot.Bot object at 0x00000254232CBE50>> exception=Forbidden('403 Forbidden (error code: 50001): Missing Access')>
Traceback (most recent call last):
  File "C:\Users\Vaishnav\.virtualenvs\Tortoise-BOT-NdGTmAqy\lib\site-packages\discord\client.py", line 312, in _run_event
    await coro(*args, **kwargs)
  File "C:\Users\Vaishnav\Projects\Tortoise-BOT\bot\bot.py", line 43, in on_ready
    await self.on_first_ready()
  File "C:\Users\Vaishnav\Projects\Tortoise-BOT\bot\bot.py", line 49, in on_first_ready
    await self.reload_tortoise_meta_cache()
  File "C:\Users\Vaishnav\Projects\Tortoise-BOT\bot\bot.py", line 55, in reload_tortoise_meta_cache
    self.tortoise_meta_cache = await self.api_client.get_server_meta()
  File "C:\Users\Vaishnav\Projects\Tortoise-BOT\bot\api_client.py", line 128, in get_server_meta
    return await self.get(f"server/meta/{guild_id}/")
  File "C:\Users\Vaishnav\Projects\Tortoise-BOT\bot\api_client.py", line 62, in get
    await self.raise_for_status(resp)
  File "C:\Users\Vaishnav\Projects\Tortoise-BOT\bot\api_client.py", line 55, in raise_for_status
    raise ResponseCodeError(response=response, response_json=response_json)
bot.api_client.ResponseCodeError: Status: 401 Response: {'detail': 'Invalid token.'}

During handling of the above exception, another exception occurred:

Traceback (most recent call last):
  File "C:\Users\Vaishnav\.virtualenvs\Tortoise-BOT-NdGTmAqy\lib\site-packages\discord\client.py", line 317, in _run_event
    await self.on_error(event_name, *args, **kwargs)
  File "C:\Users\Vaishnav\Projects\Tortoise-BOT\bot\bot.py", line 90, in on_error
    await self.log_error(msg)
  File "C:\Users\Vaishnav\Projects\Tortoise-BOT\bot\bot.py", line 101, in log_error
    await error_log_channel.send(f"```Num {count+1}/{len(split_messages)}:\n{message}```")
  File "C:\Users\Vaishnav\.virtualenvs\Tortoise-BOT-NdGTmAqy\lib\site-packages\discord\abc.py", line 870, in send
    data = await state.http.send_message(channel.id, content, tts=tts, embed=embed, nonce=nonce)
  File "C:\Users\Vaishnav\.virtualenvs\Tortoise-BOT-NdGTmAqy\lib\site-packages\discord\http.py", line 221, in request
    raise Forbidden(r, data)
discord.errors.Forbidden: 403 Forbidden (error code: 50001): Missing Access
2020-09-18 15:20:58,687 - discord.client - Received signal to terminate bot and event loop.
2020-09-18 15:20:58,687 - discord.client - Cleaning up tasks.
2020-09-18 15:20:58,688 - discord.client - Cleaning up after 4 tasks.
2020-09-18 15:20:58,871 - discord.client - Closing the event loop.
2020-09-18 15:21:01,525 - discord.client - logging in using static token
2020-09-18 15:21:05,588 - discord.gateway - Created websocket connected to wss://gateway.discord.gg?encoding=json&v=6&compress=zlib-stream
2020-09-18 15:21:05,590 - discord.gateway - Shard ID None has sent the IDENTIFY payload.
2020-09-18 15:21:08,704 - discord.gateway - Shard ID None has connected to Gateway: ["gateway-prd-main-bpf7",{"micros":118230,"calls":["discord-sessions-prd-2-53",{"micros":115519,"calls":["start_session",{"micros":82315,"calls":["api-prd-main-9qdk",{"micros":79101,"calls":["get_user",{"micros":3361},"add_authorized_ip",{"micros":9441},"get_guilds",{"micros":3658},"coros_wait",{"micros":2}]}]},"guilds_connect",{"micros":4,"calls":[]},"presence_connect",{"micros":11998,"calls":[]}]}]}] (Session ID: 06461018b7cab783b837b050c07620bb).
2020-09-18 15:21:08,723 - bot.bot - Connection to Discord established.
2020-09-18 15:21:10,731 - console - Successfully logged in as gambling bot ID:729824279990108222 	d.py version: 1.3.4 	Further logging output will go to log file..
2020-09-18 15:21:10,754 - console - loaded bot.cogs.games
2020-09-18 15:21:10,781 - console - loaded bot.cogs.other
2020-09-18 15:21:13,647 - discord.state - Processed a chunk for 1000 members in guild ID 577192344529404154.
2020-09-18 15:21:14,379 - discord.state - Somehow timed out waiting for chunks.
2020-09-18 15:21:15,262 - discord.state - Processed a chunk for 1000 members in guild ID 577192344529404154.
2020-09-18 15:21:15,310 - discord.state - Processed a chunk for 157 members in guild ID 577192344529404154.
2020-09-18 15:21:17,989 - bot.bot - on_ready event error exception!
Traceback (most recent call last):
  File "C:\Users\Vaishnav\.virtualenvs\Tortoise-BOT-NdGTmAqy\lib\site-packages\discord\client.py", line 312, in _run_event
    await coro(*args, **kwargs)
  File "C:\Users\Vaishnav\Projects\Tortoise-BOT\bot\bot.py", line 43, in on_ready
    await self.on_first_ready()
  File "C:\Users\Vaishnav\Projects\Tortoise-BOT\bot\bot.py", line 49, in on_first_ready
    await self.reload_tortoise_meta_cache()
  File "C:\Users\Vaishnav\Projects\Tortoise-BOT\bot\bot.py", line 55, in reload_tortoise_meta_cache
    self.tortoise_meta_cache = await self.api_client.get_server_meta()
  File "C:\Users\Vaishnav\Projects\Tortoise-BOT\bot\api_client.py", line 128, in get_server_meta
    return await self.get(f"server/meta/{guild_id}/")
  File "C:\Users\Vaishnav\Projects\Tortoise-BOT\bot\api_client.py", line 62, in get
    await self.raise_for_status(resp)
  File "C:\Users\Vaishnav\Projects\Tortoise-BOT\bot\api_client.py", line 55, in raise_for_status
    raise ResponseCodeError(response=response, response_json=response_json)
bot.api_client.ResponseCodeError: Status: 401 Response: {'detail': 'Invalid token.'}

2020-09-18 15:21:18,674 - asyncio - _ClientEventTask exception was never retrieved
future: <ClientEventTask state=finished event=on_ready coro=<bound method Bot.on_ready of <bot.bot.Bot object at 0x000001D4C9AABEB0>> exception=Forbidden('403 Forbidden (error code: 50001): Missing Access')>
Traceback (most recent call last):
  File "C:\Users\Vaishnav\.virtualenvs\Tortoise-BOT-NdGTmAqy\lib\site-packages\discord\client.py", line 312, in _run_event
    await coro(*args, **kwargs)
  File "C:\Users\Vaishnav\Projects\Tortoise-BOT\bot\bot.py", line 43, in on_ready
    await self.on_first_ready()
  File "C:\Users\Vaishnav\Projects\Tortoise-BOT\bot\bot.py", line 49, in on_first_ready
    await self.reload_tortoise_meta_cache()
  File "C:\Users\Vaishnav\Projects\Tortoise-BOT\bot\bot.py", line 55, in reload_tortoise_meta_cache
    self.tortoise_meta_cache = await self.api_client.get_server_meta()
  File "C:\Users\Vaishnav\Projects\Tortoise-BOT\bot\api_client.py", line 128, in get_server_meta
    return await self.get(f"server/meta/{guild_id}/")
  File "C:\Users\Vaishnav\Projects\Tortoise-BOT\bot\api_client.py", line 62, in get
    await self.raise_for_status(resp)
  File "C:\Users\Vaishnav\Projects\Tortoise-BOT\bot\api_client.py", line 55, in raise_for_status
    raise ResponseCodeError(response=response, response_json=response_json)
bot.api_client.ResponseCodeError: Status: 401 Response: {'detail': 'Invalid token.'}

During handling of the above exception, another exception occurred:

Traceback (most recent call last):
  File "C:\Users\Vaishnav\.virtualenvs\Tortoise-BOT-NdGTmAqy\lib\site-packages\discord\client.py", line 317, in _run_event
    await self.on_error(event_name, *args, **kwargs)
  File "C:\Users\Vaishnav\Projects\Tortoise-BOT\bot\bot.py", line 90, in on_error
    await self.log_error(msg)
  File "C:\Users\Vaishnav\Projects\Tortoise-BOT\bot\bot.py", line 101, in log_error
    await error_log_channel.send(f"```Num {count+1}/{len(split_messages)}:\n{message}```")
  File "C:\Users\Vaishnav\.virtualenvs\Tortoise-BOT-NdGTmAqy\lib\site-packages\discord\abc.py", line 870, in send
    data = await state.http.send_message(channel.id, content, tts=tts, embed=embed, nonce=nonce)
  File "C:\Users\Vaishnav\.virtualenvs\Tortoise-BOT-NdGTmAqy\lib\site-packages\discord\http.py", line 221, in request
    raise Forbidden(r, data)
discord.errors.Forbidden: 403 Forbidden (error code: 50001): Missing Access
2020-09-18 15:22:56,013 - discord.client - Received signal to terminate bot and event loop.
2020-09-18 15:22:56,013 - discord.client - Cleaning up tasks.
2020-09-18 15:22:56,013 - discord.client - Cleaning up after 4 tasks.
2020-09-18 15:22:56,222 - discord.client - Closing the event loop.
2020-09-18 15:22:58,602 - discord.client - logging in using static token
2020-09-18 15:23:03,081 - discord.gateway - Created websocket connected to wss://gateway.discord.gg?encoding=json&v=6&compress=zlib-stream
2020-09-18 15:23:03,083 - discord.gateway - Shard ID None has sent the IDENTIFY payload.
2020-09-18 15:23:04,070 - discord.gateway - Shard ID None has connected to Gateway: ["gateway-prd-main-9lt2",{"micros":95183,"calls":["discord-sessions-prd-2-5",{"micros":93992,"calls":["start_session",{"micros":58649,"calls":["api-prd-main-gqjg",{"micros":53892,"calls":["get_user",{"micros":6404},"add_authorized_ip",{"micros":7806},"get_guilds",{"micros":2261},"coros_wait",{"micros":1}]}]},"guilds_connect",{"micros":4,"calls":[]},"presence_connect",{"micros":26465,"calls":[]}]}]}] (Session ID: 48d506990b26a2cd637e3617813094d9).
2020-09-18 15:23:04,084 - bot.bot - Connection to Discord established.
2020-09-18 15:23:09,997 - discord.state - Processed a chunk for 1000 members in guild ID 577192344529404154.
2020-09-18 15:23:10,142 - discord.state - Processed a chunk for 1000 members in guild ID 577192344529404154.
2020-09-18 15:23:10,378 - discord.state - Processed a chunk for 157 members in guild ID 577192344529404154.
2020-09-18 15:23:10,378 - console - Successfully logged in as gambling bot ID:729824279990108222 	d.py version: 1.3.4 	Further logging output will go to log file..
2020-09-18 15:23:10,389 - console - loaded bot.cogs.games
2020-09-18 15:23:10,408 - console - loaded bot.cogs.other
2020-09-18 15:23:15,191 - bot.bot - on_ready event error exception!
Traceback (most recent call last):
  File "C:\Users\Vaishnav\.virtualenvs\Tortoise-BOT-NdGTmAqy\lib\site-packages\discord\client.py", line 312, in _run_event
    await coro(*args, **kwargs)
  File "C:\Users\Vaishnav\Projects\Tortoise-BOT\bot\bot.py", line 43, in on_ready
    await self.on_first_ready()
  File "C:\Users\Vaishnav\Projects\Tortoise-BOT\bot\bot.py", line 49, in on_first_ready
    await self.reload_tortoise_meta_cache()
  File "C:\Users\Vaishnav\Projects\Tortoise-BOT\bot\bot.py", line 55, in reload_tortoise_meta_cache
    self.tortoise_meta_cache = await self.api_client.get_server_meta()
  File "C:\Users\Vaishnav\Projects\Tortoise-BOT\bot\api_client.py", line 128, in get_server_meta
    return await self.get(f"server/meta/{guild_id}/")
  File "C:\Users\Vaishnav\Projects\Tortoise-BOT\bot\api_client.py", line 62, in get
    await self.raise_for_status(resp)
  File "C:\Users\Vaishnav\Projects\Tortoise-BOT\bot\api_client.py", line 55, in raise_for_status
    raise ResponseCodeError(response=response, response_json=response_json)
bot.api_client.ResponseCodeError: Status: 401 Response: {'detail': 'Invalid token.'}

2020-09-18 15:23:15,853 - asyncio - _ClientEventTask exception was never retrieved
future: <ClientEventTask state=finished event=on_ready coro=<bound method Bot.on_ready of <bot.bot.Bot object at 0x00000187BCFCBEB0>> exception=Forbidden('403 Forbidden (error code: 50001): Missing Access')>
Traceback (most recent call last):
  File "C:\Users\Vaishnav\.virtualenvs\Tortoise-BOT-NdGTmAqy\lib\site-packages\discord\client.py", line 312, in _run_event
    await coro(*args, **kwargs)
  File "C:\Users\Vaishnav\Projects\Tortoise-BOT\bot\bot.py", line 43, in on_ready
    await self.on_first_ready()
  File "C:\Users\Vaishnav\Projects\Tortoise-BOT\bot\bot.py", line 49, in on_first_ready
    await self.reload_tortoise_meta_cache()
  File "C:\Users\Vaishnav\Projects\Tortoise-BOT\bot\bot.py", line 55, in reload_tortoise_meta_cache
    self.tortoise_meta_cache = await self.api_client.get_server_meta()
  File "C:\Users\Vaishnav\Projects\Tortoise-BOT\bot\api_client.py", line 128, in get_server_meta
    return await self.get(f"server/meta/{guild_id}/")
  File "C:\Users\Vaishnav\Projects\Tortoise-BOT\bot\api_client.py", line 62, in get
    await self.raise_for_status(resp)
  File "C:\Users\Vaishnav\Projects\Tortoise-BOT\bot\api_client.py", line 55, in raise_for_status
    raise ResponseCodeError(response=response, response_json=response_json)
bot.api_client.ResponseCodeError: Status: 401 Response: {'detail': 'Invalid token.'}

During handling of the above exception, another exception occurred:

Traceback (most recent call last):
  File "C:\Users\Vaishnav\.virtualenvs\Tortoise-BOT-NdGTmAqy\lib\site-packages\discord\client.py", line 317, in _run_event
    await self.on_error(event_name, *args, **kwargs)
  File "C:\Users\Vaishnav\Projects\Tortoise-BOT\bot\bot.py", line 90, in on_error
    await self.log_error(msg)
  File "C:\Users\Vaishnav\Projects\Tortoise-BOT\bot\bot.py", line 101, in log_error
    await error_log_channel.send(f"```Num {count+1}/{len(split_messages)}:\n{message}```")
  File "C:\Users\Vaishnav\.virtualenvs\Tortoise-BOT-NdGTmAqy\lib\site-packages\discord\abc.py", line 870, in send
    data = await state.http.send_message(channel.id, content, tts=tts, embed=embed, nonce=nonce)
  File "C:\Users\Vaishnav\.virtualenvs\Tortoise-BOT-NdGTmAqy\lib\site-packages\discord\http.py", line 221, in request
    raise Forbidden(r, data)
discord.errors.Forbidden: 403 Forbidden (error code: 50001): Missing Access
2020-09-18 15:26:35,813 - discord.client - Received signal to terminate bot and event loop.
2020-09-18 15:26:35,813 - discord.client - Cleaning up tasks.
2020-09-18 15:26:35,813 - discord.client - Cleaning up after 4 tasks.
2020-09-18 15:26:35,991 - discord.client - Closing the event loop.
2020-09-18 15:26:38,602 - discord.client - logging in using static token
2020-09-18 15:26:42,437 - discord.gateway - Created websocket connected to wss://gateway.discord.gg?encoding=json&v=6&compress=zlib-stream
2020-09-18 15:26:42,440 - discord.gateway - Shard ID None has sent the IDENTIFY payload.
2020-09-18 15:26:43,447 - discord.gateway - Shard ID None has connected to Gateway: ["gateway-prd-main-gwhj",{"micros":111111,"calls":["discord-sessions-prd-1-12",{"micros":108085,"calls":["start_session",{"micros":48981,"calls":["api-prd-main-9qdk",{"micros":45624,"calls":["get_user",{"micros":3399},"add_authorized_ip",{"micros":1411},"get_guilds",{"micros":2338},"coros_wait",{"micros":0}]}]},"guilds_connect",{"micros":5,"calls":[]},"presence_connect",{"micros":30972,"calls":[]}]}]}] (Session ID: 4282196cf0214bd5f06e8aa9cd233926).
2020-09-18 15:26:43,460 - bot.bot - Connection to Discord established.
2020-09-18 15:26:45,462 - console - Successfully logged in as gambling bot ID:729824279990108222 	d.py version: 1.3.4 	Further logging output will go to log file..
2020-09-18 15:26:45,479 - console - loaded bot.cogs.games
2020-09-18 15:26:45,505 - console - loaded bot.cogs.other
2020-09-18 15:26:49,147 - discord.state - Somehow timed out waiting for chunks.
2020-09-18 15:26:49,521 - discord.state - Processed a chunk for 1000 members in guild ID 577192344529404154.
2020-09-18 15:26:49,661 - discord.state - Processed a chunk for 1000 members in guild ID 577192344529404154.
2020-09-18 15:26:49,967 - discord.state - Processed a chunk for 157 members in guild ID 577192344529404154.
2020-09-18 15:26:59,674 - bot.bot - on_ready event error exception!
Traceback (most recent call last):
  File "C:\Users\Vaishnav\.virtualenvs\Tortoise-BOT-NdGTmAqy\lib\site-packages\aiohttp\connector.py", line 964, in _create_direct_connection
    hosts = await asyncio.shield(self._resolve_host(
  File "C:\Users\Vaishnav\.virtualenvs\Tortoise-BOT-NdGTmAqy\lib\site-packages\aiohttp\connector.py", line 829, in _resolve_host
    addrs = await \
  File "C:\Users\Vaishnav\.virtualenvs\Tortoise-BOT-NdGTmAqy\lib\site-packages\aiohttp\resolver.py", line 29, in resolve
    infos = await self._loop.getaddrinfo(
  File "c:\users\vaishnav\appdata\local\programs\python\python38\lib\asyncio\base_events.py", line 825, in getaddrinfo
    return await self.run_in_executor(
  File "c:\users\vaishnav\appdata\local\programs\python\python38\lib\concurrent\futures\thread.py", line 57, in run
    result = self.fn(*self.args, **self.kwargs)
  File "c:\users\vaishnav\appdata\local\programs\python\python38\lib\socket.py", line 918, in getaddrinfo
    for res in _socket.getaddrinfo(host, port, family, type, proto, flags):
socket.gaierror: [Errno 11001] getaddrinfo failed

The above exception was the direct cause of the following exception:

Traceback (most recent call last):
  File "C:\Users\Vaishnav\.virtualenvs\Tortoise-BOT-NdGTmAqy\lib\site-packages\discord\client.py", line 312, in _run_event
    await coro(*args, **kwargs)
  File "C:\Users\Vaishnav\Projects\Tortoise-BOT\bot\bot.py", line 43, in on_ready
    await self.on_first_ready()
  File "C:\Users\Vaishnav\Projects\Tortoise-BOT\bot\bot.py", line 49, in on_first_ready
    await self.reload_tortoise_meta_cache()
  File "C:\Users\Vaishnav\Projects\Tortoise-BOT\bot\bot.py", line 55, in reload_tortoise_meta_cache
    self.tortoise_meta_cache = await self.api_client.get_server_meta()
  File "C:\Users\Vaishnav\Projects\Tortoise-BOT\bot\api_client.py", line 128, in get_server_meta
    return await self.get(f"server/meta/{guild_id}/")
  File "C:\Users\Vaishnav\Projects\Tortoise-BOT\bot\api_client.py", line 61, in get
    async with self.session.get(self._url_for(endpoint), **kwargs) as resp:
  File "C:\Users\Vaishnav\.virtualenvs\Tortoise-BOT-NdGTmAqy\lib\site-packages\aiohttp\client.py", line 1012, in __aenter__
    self._resp = await self._coro
  File "C:\Users\Vaishnav\.virtualenvs\Tortoise-BOT-NdGTmAqy\lib\site-packages\aiohttp\client.py", line 480, in _request
    conn = await self._connector.connect(
  File "C:\Users\Vaishnav\.virtualenvs\Tortoise-BOT-NdGTmAqy\lib\site-packages\aiohttp\connector.py", line 523, in connect
    proto = await self._create_connection(req, traces, timeout)
  File "C:\Users\Vaishnav\.virtualenvs\Tortoise-BOT-NdGTmAqy\lib\site-packages\aiohttp\connector.py", line 858, in _create_connection
    _, proto = await self._create_direct_connection(
  File "C:\Users\Vaishnav\.virtualenvs\Tortoise-BOT-NdGTmAqy\lib\site-packages\aiohttp\connector.py", line 971, in _create_direct_connection
    raise ClientConnectorError(req.connection_key, exc) from exc
aiohttp.client_exceptions.ClientConnectorError: Cannot connect to host api.tortoisecommunity.com:443 ssl:default [getaddrinfo failed]

2020-09-18 15:27:00,377 - asyncio - _ClientEventTask exception was never retrieved
future: <ClientEventTask state=finished event=on_ready coro=<bound method Bot.on_ready of <bot.bot.Bot object at 0x00000233E96FBEE0>> exception=Forbidden('403 Forbidden (error code: 50001): Missing Access')>
Traceback (most recent call last):
  File "C:\Users\Vaishnav\.virtualenvs\Tortoise-BOT-NdGTmAqy\lib\site-packages\aiohttp\connector.py", line 964, in _create_direct_connection
    hosts = await asyncio.shield(self._resolve_host(
  File "C:\Users\Vaishnav\.virtualenvs\Tortoise-BOT-NdGTmAqy\lib\site-packages\aiohttp\connector.py", line 829, in _resolve_host
    addrs = await \
  File "C:\Users\Vaishnav\.virtualenvs\Tortoise-BOT-NdGTmAqy\lib\site-packages\aiohttp\resolver.py", line 29, in resolve
    infos = await self._loop.getaddrinfo(
  File "c:\users\vaishnav\appdata\local\programs\python\python38\lib\asyncio\base_events.py", line 825, in getaddrinfo
    return await self.run_in_executor(
  File "c:\users\vaishnav\appdata\local\programs\python\python38\lib\concurrent\futures\thread.py", line 57, in run
    result = self.fn(*self.args, **self.kwargs)
  File "c:\users\vaishnav\appdata\local\programs\python\python38\lib\socket.py", line 918, in getaddrinfo
    for res in _socket.getaddrinfo(host, port, family, type, proto, flags):
socket.gaierror: [Errno 11001] getaddrinfo failed

The above exception was the direct cause of the following exception:

Traceback (most recent call last):
  File "C:\Users\Vaishnav\.virtualenvs\Tortoise-BOT-NdGTmAqy\lib\site-packages\discord\client.py", line 312, in _run_event
    await coro(*args, **kwargs)
  File "C:\Users\Vaishnav\Projects\Tortoise-BOT\bot\bot.py", line 43, in on_ready
    await self.on_first_ready()
  File "C:\Users\Vaishnav\Projects\Tortoise-BOT\bot\bot.py", line 49, in on_first_ready
    await self.reload_tortoise_meta_cache()
  File "C:\Users\Vaishnav\Projects\Tortoise-BOT\bot\bot.py", line 55, in reload_tortoise_meta_cache
    self.tortoise_meta_cache = await self.api_client.get_server_meta()
  File "C:\Users\Vaishnav\Projects\Tortoise-BOT\bot\api_client.py", line 128, in get_server_meta
    return await self.get(f"server/meta/{guild_id}/")
  File "C:\Users\Vaishnav\Projects\Tortoise-BOT\bot\api_client.py", line 61, in get
    async with self.session.get(self._url_for(endpoint), **kwargs) as resp:
  File "C:\Users\Vaishnav\.virtualenvs\Tortoise-BOT-NdGTmAqy\lib\site-packages\aiohttp\client.py", line 1012, in __aenter__
    self._resp = await self._coro
  File "C:\Users\Vaishnav\.virtualenvs\Tortoise-BOT-NdGTmAqy\lib\site-packages\aiohttp\client.py", line 480, in _request
    conn = await self._connector.connect(
  File "C:\Users\Vaishnav\.virtualenvs\Tortoise-BOT-NdGTmAqy\lib\site-packages\aiohttp\connector.py", line 523, in connect
    proto = await self._create_connection(req, traces, timeout)
  File "C:\Users\Vaishnav\.virtualenvs\Tortoise-BOT-NdGTmAqy\lib\site-packages\aiohttp\connector.py", line 858, in _create_connection
    _, proto = await self._create_direct_connection(
  File "C:\Users\Vaishnav\.virtualenvs\Tortoise-BOT-NdGTmAqy\lib\site-packages\aiohttp\connector.py", line 971, in _create_direct_connection
    raise ClientConnectorError(req.connection_key, exc) from exc
aiohttp.client_exceptions.ClientConnectorError: Cannot connect to host api.tortoisecommunity.com:443 ssl:default [getaddrinfo failed]

During handling of the above exception, another exception occurred:

Traceback (most recent call last):
  File "C:\Users\Vaishnav\.virtualenvs\Tortoise-BOT-NdGTmAqy\lib\site-packages\discord\client.py", line 317, in _run_event
    await self.on_error(event_name, *args, **kwargs)
  File "C:\Users\Vaishnav\Projects\Tortoise-BOT\bot\bot.py", line 90, in on_error
    await self.log_error(msg)
  File "C:\Users\Vaishnav\Projects\Tortoise-BOT\bot\bot.py", line 101, in log_error
    await error_log_channel.send(f"```Num {count+1}/{len(split_messages)}:\n{message}```")
  File "C:\Users\Vaishnav\.virtualenvs\Tortoise-BOT-NdGTmAqy\lib\site-packages\discord\abc.py", line 870, in send
    data = await state.http.send_message(channel.id, content, tts=tts, embed=embed, nonce=nonce)
  File "C:\Users\Vaishnav\.virtualenvs\Tortoise-BOT-NdGTmAqy\lib\site-packages\discord\http.py", line 221, in request
    raise Forbidden(r, data)
discord.errors.Forbidden: 403 Forbidden (error code: 50001): Missing Access
2020-09-18 16:08:00,171 - discord.gateway - Websocket closed with 1006 (), attempting a reconnect.
2020-09-18 16:08:00,171 - discord.client - Got a request to RESUME the websocket.
2020-09-18 16:08:00,171 - bot.bot - Connection to Discord lost.
2020-09-18 16:08:03,708 - discord.gateway - Created websocket connected to wss://gateway.discord.gg?encoding=json&v=6&compress=zlib-stream
2020-09-18 16:08:03,715 - discord.gateway - Shard ID None has sent the RESUME payload.
2020-09-18 16:08:04,603 - discord.gateway - Shard ID None has successfully RESUMED session 4282196cf0214bd5f06e8aa9cd233926 under trace ["gateway-prd-main-tm2c",{"micros":1547,"calls":["discord-sessions-prd-1-12",{"micros":86}]}].
2020-09-18 16:08:41,425 - discord.gateway - Shard ID None has stopped responding to the gateway. Closing and restarting.
2020-09-18 16:25:17,575 - discord.client - Received signal to terminate bot and event loop.
2020-09-18 16:25:17,575 - discord.client - Cleaning up tasks.
2020-09-18 16:25:17,575 - discord.client - Cleaning up after 4 tasks.
2020-09-18 16:25:20,102 - discord.client - Closing the event loop.
