2020-09-15 20:59:25,434 - discord.client - logging in using static token
2020-09-15 20:59:30,150 - discord.gateway - Created websocket connected to wss://gateway.discord.gg?encoding=json&v=6&compress=zlib-stream
2020-09-15 20:59:31,504 - discord.gateway - Shard ID None has sent the IDENTIFY payload.
2020-09-15 20:59:32,967 - discord.gateway - Shard ID None has connected to Gateway: ["gateway-prd-main-q160",{"micros":94464,"calls":["discord-sessions-prd-2-14",{"micros":87729,"calls":["start_session",{"micros":72310,"calls":["api-prd-main-knsr",{"micros":66805,"calls":["get_user",{"micros":7865},"add_authorized_ip",{"micros":3212},"get_guilds",{"micros":10169},"coros_wait",{"micros":1}]}]},"guilds_connect",{"micros":112,"calls":[]},"presence_connect",{"micros":3565,"calls":[]}]}]}] (Session ID: fc388d4639710d9cd08ef506305b8d75).
2020-09-15 20:59:32,982 - bot.bot - Connection to Discord established.
2020-09-15 20:59:35,000 - console - Successfully logged in as gambling bot ID:729824279990108222 	d.py version: 1.3.4 	Further logging output will go to log file..
2020-09-15 20:59:35,022 - console - loaded bot.cogs.games
2020-09-15 20:59:37,551 - discord.state - Processed a chunk for 1000 members in guild ID 577192344529404154.
2020-09-15 20:59:38,527 - discord.state - Somehow timed out waiting for chunks.
2020-09-15 20:59:38,661 - discord.state - Processed a chunk for 1000 members in guild ID 577192344529404154.
2020-09-15 20:59:39,825 - bot.bot - on_ready event error exception!
Traceback (most recent call last):
  File "C:\Users\Vaishnav\.virtualenvs\Tortoise-BOT-NdGTmAqy\lib\site-packages\discord\client.py", line 312, in _run_event
    await coro(*args, **kwargs)
  File "C:\Users\Vaishnav\Projects\Tortoise-BOT\bot\bot.py", line 43, in on_ready
    await self.on_first_ready()
  File "C:\Users\Vaishnav\Projects\Tortoise-BOT\bot\bot.py", line 49, in on_first_ready
    await self.reload_tortoise_meta_cache()
  File "C:\Users\Vaishnav\Projects\Tortoise-BOT\bot\bot.py", line 55, in reload_tortoise_meta_cache
    self.tortoise_meta_cache = await self.api_client.get_server_meta()
  File "C:\Users\Vaishnav\Projects\Tortoise-BOT\bot\api_client.py", line 128, in get_server_meta
    return await self.get(f"server/meta/{guild_id}/")
  File "C:\Users\Vaishnav\Projects\Tortoise-BOT\bot\api_client.py", line 62, in get
    await self.raise_for_status(resp)
  File "C:\Users\Vaishnav\Projects\Tortoise-BOT\bot\api_client.py", line 55, in raise_for_status
    raise ResponseCodeError(response=response, response_json=response_json)
bot.api_client.ResponseCodeError: Status: 401 Response: {'detail': 'Invalid token.'}

2020-09-15 20:59:39,889 - discord.state - Processed a chunk for 137 members in guild ID 577192344529404154.
2020-09-15 20:59:40,542 - asyncio - _ClientEventTask exception was never retrieved
future: <ClientEventTask state=finished event=on_ready coro=<bound method Bot.on_ready of <bot.bot.Bot object at 0x000002A50856CEB0>> exception=Forbidden('403 Forbidden (error code: 50001): Missing Access')>
Traceback (most recent call last):
  File "C:\Users\Vaishnav\.virtualenvs\Tortoise-BOT-NdGTmAqy\lib\site-packages\discord\client.py", line 312, in _run_event
    await coro(*args, **kwargs)
  File "C:\Users\Vaishnav\Projects\Tortoise-BOT\bot\bot.py", line 43, in on_ready
    await self.on_first_ready()
  File "C:\Users\Vaishnav\Projects\Tortoise-BOT\bot\bot.py", line 49, in on_first_ready
    await self.reload_tortoise_meta_cache()
  File "C:\Users\Vaishnav\Projects\Tortoise-BOT\bot\bot.py", line 55, in reload_tortoise_meta_cache
    self.tortoise_meta_cache = await self.api_client.get_server_meta()
  File "C:\Users\Vaishnav\Projects\Tortoise-BOT\bot\api_client.py", line 128, in get_server_meta
    return await self.get(f"server/meta/{guild_id}/")
  File "C:\Users\Vaishnav\Projects\Tortoise-BOT\bot\api_client.py", line 62, in get
    await self.raise_for_status(resp)
  File "C:\Users\Vaishnav\Projects\Tortoise-BOT\bot\api_client.py", line 55, in raise_for_status
    raise ResponseCodeError(response=response, response_json=response_json)
bot.api_client.ResponseCodeError: Status: 401 Response: {'detail': 'Invalid token.'}

During handling of the above exception, another exception occurred:

Traceback (most recent call last):
  File "C:\Users\Vaishnav\.virtualenvs\Tortoise-BOT-NdGTmAqy\lib\site-packages\discord\client.py", line 317, in _run_event
    await self.on_error(event_name, *args, **kwargs)
  File "C:\Users\Vaishnav\Projects\Tortoise-BOT\bot\bot.py", line 90, in on_error
    await self.log_error(msg)
  File "C:\Users\Vaishnav\Projects\Tortoise-BOT\bot\bot.py", line 101, in log_error
    await error_log_channel.send(f"```Num {count+1}/{len(split_messages)}:\n{message}```")
  File "C:\Users\Vaishnav\.virtualenvs\Tortoise-BOT-NdGTmAqy\lib\site-packages\discord\abc.py", line 870, in send
    data = await state.http.send_message(channel.id, content, tts=tts, embed=embed, nonce=nonce)
  File "C:\Users\Vaishnav\.virtualenvs\Tortoise-BOT-NdGTmAqy\lib\site-packages\discord\http.py", line 221, in request
    raise Forbidden(r, data)
discord.errors.Forbidden: 403 Forbidden (error code: 50001): Missing Access
2020-09-15 21:01:09,818 - discord.gateway - Can't keep up, websocket is 15.8s behind.
2020-09-15 21:05:04,620 - discord.client - Received signal to terminate bot and event loop.
2020-09-15 21:05:04,620 - discord.client - Cleaning up tasks.
2020-09-15 21:05:04,620 - discord.client - Cleaning up after 4 tasks.
2020-09-15 21:05:04,797 - discord.client - Closing the event loop.
2020-09-15 21:05:12,981 - discord.client - logging in using static token
2020-09-15 21:05:16,695 - discord.gateway - Created websocket connected to wss://gateway.discord.gg?encoding=json&v=6&compress=zlib-stream
2020-09-15 21:05:16,698 - discord.gateway - Shard ID None has sent the IDENTIFY payload.
2020-09-15 21:05:17,754 - discord.gateway - Shard ID None has connected to Gateway: ["gateway-prd-main-pwrr",{"micros":65629,"calls":["discord-sessions-prd-1-12",{"micros":63987,"calls":["start_session",{"micros":35851,"calls":["api-prd-main-vv0w",{"micros":33536,"calls":["get_user",{"micros":1923},"add_authorized_ip",{"micros":1499},"get_guilds",{"micros":7194},"coros_wait",{"micros":1}]}]},"guilds_connect",{"micros":3,"calls":[]},"presence_connect",{"micros":13532,"calls":[]}]}]}] (Session ID: 9bb0670f600c4559296db33ecd6cacfd).
2020-09-15 21:05:17,771 - bot.bot - Connection to Discord established.
2020-09-15 21:05:23,000 - discord.state - Processed a chunk for 1000 members in guild ID 577192344529404154.
2020-09-15 21:05:23,717 - discord.state - Processed a chunk for 1000 members in guild ID 577192344529404154.
2020-09-15 21:05:23,722 - discord.state - Processed a chunk for 137 members in guild ID 577192344529404154.
2020-09-15 21:05:23,723 - console - Successfully logged in as gambling bot ID:729824279990108222 	d.py version: 1.3.4 	Further logging output will go to log file..
2020-09-15 21:05:23,727 - console - Failed to load cog bot.cogs.games - traceback:['Traceback (most recent call last):\n', '  File "C:\\Users\\Vaishnav\\.virtualenvs\\Tortoise-BOT-NdGTmAqy\\lib\\site-packages\\discord\\ext\\commands\\bot.py", line 596, in _load_from_module_spec\n    spec.loader.exec_module(lib)\n', '  File "<frozen importlib._bootstrap_external>", line 779, in exec_module\n', '  File "<frozen importlib._bootstrap_external>", line 916, in get_code\n', '  File "<frozen importlib._bootstrap_external>", line 846, in source_to_code\n', '  File "<frozen importlib._bootstrap>", line 219, in _call_with_frames_removed\n', '  File "C:\\Users\\Vaishnav\\Projects\\Tortoise-BOT\\bot\\cogs\\games.py", line 130\n', '    """Initializes single/multiplayer blackjack game"""\n', '    ^\n', 'SyntaxError: invalid syntax\n', '\nThe above exception was the direct cause of the following exception:\n\n', 'Traceback (most recent call last):\n', '  File "C:\\Users\\Vaishnav\\Projects\\Tortoise-BOT\\bot\\bot.py", line 69, in load_extensions\n    self.load_extension(dotted_path)\n', '  File "C:\\Users\\Vaishnav\\.virtualenvs\\Tortoise-BOT-NdGTmAqy\\lib\\site-packages\\discord\\ext\\commands\\bot.py", line 653, in load_extension\n    self._load_from_module_spec(spec, name)\n', '  File "C:\\Users\\Vaishnav\\.virtualenvs\\Tortoise-BOT-NdGTmAqy\\lib\\site-packages\\discord\\ext\\commands\\bot.py", line 599, in _load_from_module_spec\n    raise errors.ExtensionFailed(key, e) from e\n', "discord.ext.commands.errors.ExtensionFailed: Extension 'bot.cogs.games' raised an error: SyntaxError: invalid syntax (games.py, line 130)\n"]
2020-09-15 21:05:25,818 - discord.client - Received signal to terminate bot and event loop.
2020-09-15 21:05:25,819 - discord.client - Cleaning up tasks.
2020-09-15 21:05:25,819 - discord.client - Cleaning up after 5 tasks.
2020-09-15 21:05:25,947 - discord.client - Closing the event loop.
2020-09-15 21:06:13,657 - discord.client - logging in using static token
2020-09-15 21:06:19,965 - discord.gateway - Created websocket connected to wss://gateway.discord.gg?encoding=json&v=6&compress=zlib-stream
2020-09-15 21:06:19,969 - discord.gateway - Shard ID None has sent the IDENTIFY payload.
2020-09-15 21:06:21,025 - discord.gateway - Shard ID None has connected to Gateway: ["gateway-prd-main-0cct",{"micros":65313,"calls":["discord-sessions-prd-2-3",{"micros":62253,"calls":["start_session",{"micros":57180,"calls":["api-prd-main-315z",{"micros":53277,"calls":["get_user",{"micros":7115},"add_authorized_ip",{"micros":3695},"get_guilds",{"micros":2429},"coros_wait",{"micros":1}]}]},"guilds_connect",{"micros":9,"calls":[]},"presence_connect",{"micros":1576,"calls":[]}]}]}] (Session ID: 062072b38ce5cdac8de839e69b2916f7).
2020-09-15 21:06:21,040 - bot.bot - Connection to Discord established.
2020-09-15 21:06:23,045 - console - Successfully logged in as gambling bot ID:729824279990108222 	d.py version: 1.3.4 	Further logging output will go to log file..
2020-09-15 21:06:23,053 - console - Failed to load cog bot.cogs.games - traceback:['Traceback (most recent call last):\n', '  File "C:\\Users\\Vaishnav\\.virtualenvs\\Tortoise-BOT-NdGTmAqy\\lib\\site-packages\\discord\\ext\\commands\\bot.py", line 596, in _load_from_module_spec\n    spec.loader.exec_module(lib)\n', '  File "<frozen importlib._bootstrap_external>", line 779, in exec_module\n', '  File "<frozen importlib._bootstrap_external>", line 916, in get_code\n', '  File "<frozen importlib._bootstrap_external>", line 846, in source_to_code\n', '  File "<frozen importlib._bootstrap>", line 219, in _call_with_frames_removed\n', '  File "C:\\Users\\Vaishnav\\Projects\\Tortoise-BOT\\bot\\cogs\\games.py", line 130\n', '    """Initializes single/multiplayer blackjack game"""\n', '    ^\n', 'SyntaxError: invalid syntax\n', '\nThe above exception was the direct cause of the following exception:\n\n', 'Traceback (most recent call last):\n', '  File "C:\\Users\\Vaishnav\\Projects\\Tortoise-BOT\\bot\\bot.py", line 69, in load_extensions\n    self.load_extension(dotted_path)\n', '  File "C:\\Users\\Vaishnav\\.virtualenvs\\Tortoise-BOT-NdGTmAqy\\lib\\site-packages\\discord\\ext\\commands\\bot.py", line 653, in load_extension\n    self._load_from_module_spec(spec, name)\n', '  File "C:\\Users\\Vaishnav\\.virtualenvs\\Tortoise-BOT-NdGTmAqy\\lib\\site-packages\\discord\\ext\\commands\\bot.py", line 599, in _load_from_module_spec\n    raise errors.ExtensionFailed(key, e) from e\n', "discord.ext.commands.errors.ExtensionFailed: Extension 'bot.cogs.games' raised an error: SyntaxError: invalid syntax (games.py, line 130)\n"]
2020-09-15 21:06:26,760 - discord.state - Processed a chunk for 1000 members in guild ID 577192344529404154.
2020-09-15 21:06:27,281 - discord.state - Processed a chunk for 1000 members in guild ID 577192344529404154.
2020-09-15 21:06:27,312 - discord.state - Processed a chunk for 137 members in guild ID 577192344529404154.
2020-09-15 21:06:28,456 - bot.bot - on_ready event error exception!
Traceback (most recent call last):
  File "C:\Users\Vaishnav\.virtualenvs\Tortoise-BOT-NdGTmAqy\lib\site-packages\discord\client.py", line 312, in _run_event
    await coro(*args, **kwargs)
  File "C:\Users\Vaishnav\Projects\Tortoise-BOT\bot\bot.py", line 43, in on_ready
    await self.on_first_ready()
  File "C:\Users\Vaishnav\Projects\Tortoise-BOT\bot\bot.py", line 49, in on_first_ready
    await self.reload_tortoise_meta_cache()
  File "C:\Users\Vaishnav\Projects\Tortoise-BOT\bot\bot.py", line 55, in reload_tortoise_meta_cache
    self.tortoise_meta_cache = await self.api_client.get_server_meta()
  File "C:\Users\Vaishnav\Projects\Tortoise-BOT\bot\api_client.py", line 128, in get_server_meta
    return await self.get(f"server/meta/{guild_id}/")
  File "C:\Users\Vaishnav\Projects\Tortoise-BOT\bot\api_client.py", line 62, in get
    await self.raise_for_status(resp)
  File "C:\Users\Vaishnav\Projects\Tortoise-BOT\bot\api_client.py", line 55, in raise_for_status
    raise ResponseCodeError(response=response, response_json=response_json)
bot.api_client.ResponseCodeError: Status: 401 Response: {'detail': 'Invalid token.'}

2020-09-15 21:06:29,253 - asyncio - _ClientEventTask exception was never retrieved
future: <ClientEventTask state=finished event=on_ready coro=<bound method Bot.on_ready of <bot.bot.Bot object at 0x000002956B1FAF70>> exception=Forbidden('403 Forbidden (error code: 50001): Missing Access')>
Traceback (most recent call last):
  File "C:\Users\Vaishnav\.virtualenvs\Tortoise-BOT-NdGTmAqy\lib\site-packages\discord\client.py", line 312, in _run_event
    await coro(*args, **kwargs)
  File "C:\Users\Vaishnav\Projects\Tortoise-BOT\bot\bot.py", line 43, in on_ready
    await self.on_first_ready()
  File "C:\Users\Vaishnav\Projects\Tortoise-BOT\bot\bot.py", line 49, in on_first_ready
    await self.reload_tortoise_meta_cache()
  File "C:\Users\Vaishnav\Projects\Tortoise-BOT\bot\bot.py", line 55, in reload_tortoise_meta_cache
    self.tortoise_meta_cache = await self.api_client.get_server_meta()
  File "C:\Users\Vaishnav\Projects\Tortoise-BOT\bot\api_client.py", line 128, in get_server_meta
    return await self.get(f"server/meta/{guild_id}/")
  File "C:\Users\Vaishnav\Projects\Tortoise-BOT\bot\api_client.py", line 62, in get
    await self.raise_for_status(resp)
  File "C:\Users\Vaishnav\Projects\Tortoise-BOT\bot\api_client.py", line 55, in raise_for_status
    raise ResponseCodeError(response=response, response_json=response_json)
bot.api_client.ResponseCodeError: Status: 401 Response: {'detail': 'Invalid token.'}

During handling of the above exception, another exception occurred:

Traceback (most recent call last):
  File "C:\Users\Vaishnav\.virtualenvs\Tortoise-BOT-NdGTmAqy\lib\site-packages\discord\client.py", line 317, in _run_event
    await self.on_error(event_name, *args, **kwargs)
  File "C:\Users\Vaishnav\Projects\Tortoise-BOT\bot\bot.py", line 90, in on_error
    await self.log_error(msg)
  File "C:\Users\Vaishnav\Projects\Tortoise-BOT\bot\bot.py", line 101, in log_error
    await error_log_channel.send(f"```Num {count+1}/{len(split_messages)}:\n{message}```")
  File "C:\Users\Vaishnav\.virtualenvs\Tortoise-BOT-NdGTmAqy\lib\site-packages\discord\abc.py", line 870, in send
    data = await state.http.send_message(channel.id, content, tts=tts, embed=embed, nonce=nonce)
  File "C:\Users\Vaishnav\.virtualenvs\Tortoise-BOT-NdGTmAqy\lib\site-packages\discord\http.py", line 221, in request
    raise Forbidden(r, data)
discord.errors.Forbidden: 403 Forbidden (error code: 50001): Missing Access
2020-09-15 21:06:30,591 - discord.client - Received signal to terminate bot and event loop.
2020-09-15 21:06:30,591 - discord.client - Cleaning up tasks.
2020-09-15 21:06:30,592 - discord.client - Cleaning up after 4 tasks.
2020-09-15 21:06:30,833 - discord.client - Closing the event loop.
2020-09-15 21:25:27,070 - discord.client - logging in using static token
2020-09-15 21:25:33,215 - discord.gateway - Created websocket connected to wss://gateway.discord.gg?encoding=json&v=6&compress=zlib-stream
2020-09-15 21:25:33,216 - discord.gateway - Shard ID None has sent the IDENTIFY payload.
2020-09-15 21:25:34,333 - discord.gateway - Shard ID None has connected to Gateway: ["gateway-prd-main-8mwj",{"micros":107153,"calls":["discord-sessions-prd-2-34",{"micros":97316,"calls":["start_session",{"micros":76040,"calls":["api-prd-main-qkcz",{"micros":73064,"calls":["get_user",{"micros":8665},"add_authorized_ip",{"micros":1758},"get_guilds",{"micros":10299},"coros_wait",{"micros":1}]}]},"guilds_connect",{"micros":5,"calls":[]},"presence_connect",{"micros":6826,"calls":[]}]}]}] (Session ID: 79e9140411ed86c8005c4545fa7a68b2).
2020-09-15 21:25:34,344 - bot.bot - Connection to Discord established.
2020-09-15 21:25:36,352 - console - Successfully logged in as gambling bot ID:729824279990108222 	d.py version: 1.3.4 	Further logging output will go to log file..
2020-09-15 21:25:36,372 - console - loaded bot.cogs.games
2020-09-15 21:25:39,182 - discord.state - Processed a chunk for 1000 members in guild ID 577192344529404154.
2020-09-15 21:25:40,080 - discord.state - Somehow timed out waiting for chunks.
2020-09-15 21:25:40,270 - discord.state - Processed a chunk for 1000 members in guild ID 577192344529404154.
2020-09-15 21:25:40,464 - discord.state - Processed a chunk for 137 members in guild ID 577192344529404154.
2020-09-15 21:25:48,623 - bot.bot - on_ready event error exception!
Traceback (most recent call last):
  File "C:\Users\Vaishnav\.virtualenvs\Tortoise-BOT-NdGTmAqy\lib\site-packages\discord\client.py", line 312, in _run_event
    await coro(*args, **kwargs)
  File "C:\Users\Vaishnav\Projects\Tortoise-BOT\bot\bot.py", line 43, in on_ready
    await self.on_first_ready()
  File "C:\Users\Vaishnav\Projects\Tortoise-BOT\bot\bot.py", line 49, in on_first_ready
    await self.reload_tortoise_meta_cache()
  File "C:\Users\Vaishnav\Projects\Tortoise-BOT\bot\bot.py", line 55, in reload_tortoise_meta_cache
    self.tortoise_meta_cache = await self.api_client.get_server_meta()
  File "C:\Users\Vaishnav\Projects\Tortoise-BOT\bot\api_client.py", line 128, in get_server_meta
    return await self.get(f"server/meta/{guild_id}/")
  File "C:\Users\Vaishnav\Projects\Tortoise-BOT\bot\api_client.py", line 62, in get
    await self.raise_for_status(resp)
  File "C:\Users\Vaishnav\Projects\Tortoise-BOT\bot\api_client.py", line 55, in raise_for_status
    raise ResponseCodeError(response=response, response_json=response_json)
bot.api_client.ResponseCodeError: Status: 401 Response: {'detail': 'Invalid token.'}

2020-09-15 21:25:51,515 - asyncio - _ClientEventTask exception was never retrieved
future: <ClientEventTask state=finished event=on_ready coro=<bound method Bot.on_ready of <bot.bot.Bot object at 0x0000022C99B6CEE0>> exception=Forbidden('403 Forbidden (error code: 50001): Missing Access')>
Traceback (most recent call last):
  File "C:\Users\Vaishnav\.virtualenvs\Tortoise-BOT-NdGTmAqy\lib\site-packages\discord\client.py", line 312, in _run_event
    await coro(*args, **kwargs)
  File "C:\Users\Vaishnav\Projects\Tortoise-BOT\bot\bot.py", line 43, in on_ready
    await self.on_first_ready()
  File "C:\Users\Vaishnav\Projects\Tortoise-BOT\bot\bot.py", line 49, in on_first_ready
    await self.reload_tortoise_meta_cache()
  File "C:\Users\Vaishnav\Projects\Tortoise-BOT\bot\bot.py", line 55, in reload_tortoise_meta_cache
    self.tortoise_meta_cache = await self.api_client.get_server_meta()
  File "C:\Users\Vaishnav\Projects\Tortoise-BOT\bot\api_client.py", line 128, in get_server_meta
    return await self.get(f"server/meta/{guild_id}/")
  File "C:\Users\Vaishnav\Projects\Tortoise-BOT\bot\api_client.py", line 62, in get
    await self.raise_for_status(resp)
  File "C:\Users\Vaishnav\Projects\Tortoise-BOT\bot\api_client.py", line 55, in raise_for_status
    raise ResponseCodeError(response=response, response_json=response_json)
bot.api_client.ResponseCodeError: Status: 401 Response: {'detail': 'Invalid token.'}

During handling of the above exception, another exception occurred:

Traceback (most recent call last):
  File "C:\Users\Vaishnav\.virtualenvs\Tortoise-BOT-NdGTmAqy\lib\site-packages\discord\client.py", line 317, in _run_event
    await self.on_error(event_name, *args, **kwargs)
  File "C:\Users\Vaishnav\Projects\Tortoise-BOT\bot\bot.py", line 90, in on_error
    await self.log_error(msg)
  File "C:\Users\Vaishnav\Projects\Tortoise-BOT\bot\bot.py", line 101, in log_error
    await error_log_channel.send(f"```Num {count+1}/{len(split_messages)}:\n{message}```")
  File "C:\Users\Vaishnav\.virtualenvs\Tortoise-BOT-NdGTmAqy\lib\site-packages\discord\abc.py", line 870, in send
    data = await state.http.send_message(channel.id, content, tts=tts, embed=embed, nonce=nonce)
  File "C:\Users\Vaishnav\.virtualenvs\Tortoise-BOT-NdGTmAqy\lib\site-packages\discord\http.py", line 221, in request
    raise Forbidden(r, data)
discord.errors.Forbidden: 403 Forbidden (error code: 50001): Missing Access
2020-09-15 21:29:49,132 - discord.client - Received signal to terminate bot and event loop.
2020-09-15 21:29:49,132 - discord.client - Cleaning up tasks.
2020-09-15 21:29:49,132 - discord.client - Cleaning up after 4 tasks.
2020-09-15 21:29:49,275 - discord.client - Closing the event loop.
2020-09-15 21:29:55,795 - discord.client - logging in using static token
2020-09-15 21:30:00,447 - discord.gateway - Created websocket connected to wss://gateway.discord.gg?encoding=json&v=6&compress=zlib-stream
2020-09-15 21:30:00,450 - discord.gateway - Shard ID None has sent the IDENTIFY payload.
2020-09-15 21:30:01,464 - discord.gateway - Shard ID None has connected to Gateway: ["gateway-prd-main-61fc",{"micros":70148,"calls":["discord-sessions-prd-2-35",{"micros":64761,"calls":["start_session",{"micros":52518,"calls":["api-prd-main-cb2m",{"micros":49278,"calls":["get_user",{"micros":3696},"add_authorized_ip",{"micros":1648},"get_guilds",{"micros":2571},"coros_wait",{"micros":1}]}]},"guilds_connect",{"micros":4,"calls":[]},"presence_connect",{"micros":2,"calls":[]}]}]}] (Session ID: abc30338244eaba804f6546d869776c6).
2020-09-15 21:30:01,479 - bot.bot - Connection to Discord established.
2020-09-15 21:30:06,148 - discord.state - Processed a chunk for 1000 members in guild ID 577192344529404154.
2020-09-15 21:30:06,433 - discord.state - Processed a chunk for 1000 members in guild ID 577192344529404154.
2020-09-15 21:30:06,445 - discord.state - Processed a chunk for 137 members in guild ID 577192344529404154.
2020-09-15 21:30:06,446 - console - Successfully logged in as gambling bot ID:729824279990108222 	d.py version: 1.3.4 	Further logging output will go to log file..
2020-09-15 21:30:06,464 - console - loaded bot.cogs.games
2020-09-15 21:30:16,168 - bot.bot - on_ready event error exception!
Traceback (most recent call last):
  File "C:\Users\Vaishnav\.virtualenvs\Tortoise-BOT-NdGTmAqy\lib\site-packages\discord\client.py", line 312, in _run_event
    await coro(*args, **kwargs)
  File "C:\Users\Vaishnav\Projects\Tortoise-BOT\bot\bot.py", line 43, in on_ready
    await self.on_first_ready()
  File "C:\Users\Vaishnav\Projects\Tortoise-BOT\bot\bot.py", line 49, in on_first_ready
    await self.reload_tortoise_meta_cache()
  File "C:\Users\Vaishnav\Projects\Tortoise-BOT\bot\bot.py", line 55, in reload_tortoise_meta_cache
    self.tortoise_meta_cache = await self.api_client.get_server_meta()
  File "C:\Users\Vaishnav\Projects\Tortoise-BOT\bot\api_client.py", line 128, in get_server_meta
    return await self.get(f"server/meta/{guild_id}/")
  File "C:\Users\Vaishnav\Projects\Tortoise-BOT\bot\api_client.py", line 62, in get
    await self.raise_for_status(resp)
  File "C:\Users\Vaishnav\Projects\Tortoise-BOT\bot\api_client.py", line 55, in raise_for_status
    raise ResponseCodeError(response=response, response_json=response_json)
bot.api_client.ResponseCodeError: Status: 401 Response: {'detail': 'Invalid token.'}

2020-09-15 21:30:17,936 - asyncio - _ClientEventTask exception was never retrieved
future: <ClientEventTask state=finished event=on_ready coro=<bound method Bot.on_ready of <bot.bot.Bot object at 0x00000199FFBCAFA0>> exception=Forbidden('403 Forbidden (error code: 50001): Missing Access')>
Traceback (most recent call last):
  File "C:\Users\Vaishnav\.virtualenvs\Tortoise-BOT-NdGTmAqy\lib\site-packages\discord\client.py", line 312, in _run_event
    await coro(*args, **kwargs)
  File "C:\Users\Vaishnav\Projects\Tortoise-BOT\bot\bot.py", line 43, in on_ready
    await self.on_first_ready()
  File "C:\Users\Vaishnav\Projects\Tortoise-BOT\bot\bot.py", line 49, in on_first_ready
    await self.reload_tortoise_meta_cache()
  File "C:\Users\Vaishnav\Projects\Tortoise-BOT\bot\bot.py", line 55, in reload_tortoise_meta_cache
    self.tortoise_meta_cache = await self.api_client.get_server_meta()
  File "C:\Users\Vaishnav\Projects\Tortoise-BOT\bot\api_client.py", line 128, in get_server_meta
    return await self.get(f"server/meta/{guild_id}/")
  File "C:\Users\Vaishnav\Projects\Tortoise-BOT\bot\api_client.py", line 62, in get
    await self.raise_for_status(resp)
  File "C:\Users\Vaishnav\Projects\Tortoise-BOT\bot\api_client.py", line 55, in raise_for_status
    raise ResponseCodeError(response=response, response_json=response_json)
bot.api_client.ResponseCodeError: Status: 401 Response: {'detail': 'Invalid token.'}

During handling of the above exception, another exception occurred:

Traceback (most recent call last):
  File "C:\Users\Vaishnav\.virtualenvs\Tortoise-BOT-NdGTmAqy\lib\site-packages\discord\client.py", line 317, in _run_event
    await self.on_error(event_name, *args, **kwargs)
  File "C:\Users\Vaishnav\Projects\Tortoise-BOT\bot\bot.py", line 90, in on_error
    await self.log_error(msg)
  File "C:\Users\Vaishnav\Projects\Tortoise-BOT\bot\bot.py", line 101, in log_error
    await error_log_channel.send(f"```Num {count+1}/{len(split_messages)}:\n{message}```")
  File "C:\Users\Vaishnav\.virtualenvs\Tortoise-BOT-NdGTmAqy\lib\site-packages\discord\abc.py", line 870, in send
    data = await state.http.send_message(channel.id, content, tts=tts, embed=embed, nonce=nonce)
  File "C:\Users\Vaishnav\.virtualenvs\Tortoise-BOT-NdGTmAqy\lib\site-packages\discord\http.py", line 221, in request
    raise Forbidden(r, data)
discord.errors.Forbidden: 403 Forbidden (error code: 50001): Missing Access
2020-09-15 21:30:23,875 - discord.client - Received signal to terminate bot and event loop.
2020-09-15 21:30:23,875 - discord.client - Cleaning up tasks.
2020-09-15 21:30:23,876 - discord.client - Cleaning up after 4 tasks.
2020-09-15 21:30:24,315 - discord.client - Closing the event loop.
2020-09-15 21:36:24,432 - discord.client - logging in using static token
2020-09-15 21:36:28,093 - discord.gateway - Created websocket connected to wss://gateway.discord.gg?encoding=json&v=6&compress=zlib-stream
2020-09-15 21:36:28,098 - discord.gateway - Shard ID None has sent the IDENTIFY payload.
2020-09-15 21:36:36,161 - discord.gateway - Shard ID None has connected to Gateway: ["gateway-prd-main-97qw",{"micros":7069396,"calls":["discord-sessions-prd-1-3",{"micros":62781,"calls":["start_session",{"micros":57626,"calls":["api-prd-main-0t06",{"micros":55023,"calls":["get_user",{"micros":3757},"add_authorized_ip",{"micros":2734},"get_guilds",{"micros":4412},"coros_wait",{"micros":2}]}]},"guilds_connect",{"micros":3,"calls":[]},"presence_connect",{"micros":1,"calls":[]}]}]}] (Session ID: 03030c0a930f7964e4693e0272cf5316).
2020-09-15 21:36:36,176 - bot.bot - Connection to Discord established.
2020-09-15 21:36:43,377 - discord.state - Processed a chunk for 1000 members in guild ID 577192344529404154.
2020-09-15 21:36:43,707 - discord.state - Processed a chunk for 1000 members in guild ID 577192344529404154.
2020-09-15 21:36:43,712 - discord.state - Processed a chunk for 137 members in guild ID 577192344529404154.
2020-09-15 21:36:43,712 - console - Successfully logged in as gambling bot ID:729824279990108222 	d.py version: 1.3.4 	Further logging output will go to log file..
2020-09-15 21:36:43,724 - console - loaded bot.cogs.games
2020-09-15 21:36:54,414 - bot.bot - on_ready event error exception!
Traceback (most recent call last):
  File "C:\Users\Vaishnav\.virtualenvs\Tortoise-BOT-NdGTmAqy\lib\site-packages\discord\client.py", line 312, in _run_event
    await coro(*args, **kwargs)
  File "C:\Users\Vaishnav\Projects\Tortoise-BOT\bot\bot.py", line 43, in on_ready
    await self.on_first_ready()
  File "C:\Users\Vaishnav\Projects\Tortoise-BOT\bot\bot.py", line 49, in on_first_ready
    await self.reload_tortoise_meta_cache()
  File "C:\Users\Vaishnav\Projects\Tortoise-BOT\bot\bot.py", line 55, in reload_tortoise_meta_cache
    self.tortoise_meta_cache = await self.api_client.get_server_meta()
  File "C:\Users\Vaishnav\Projects\Tortoise-BOT\bot\api_client.py", line 128, in get_server_meta
    return await self.get(f"server/meta/{guild_id}/")
  File "C:\Users\Vaishnav\Projects\Tortoise-BOT\bot\api_client.py", line 62, in get
    await self.raise_for_status(resp)
  File "C:\Users\Vaishnav\Projects\Tortoise-BOT\bot\api_client.py", line 55, in raise_for_status
    raise ResponseCodeError(response=response, response_json=response_json)
bot.api_client.ResponseCodeError: Status: 401 Response: {'detail': 'Invalid token.'}

2020-09-15 21:36:55,938 - asyncio - _ClientEventTask exception was never retrieved
future: <ClientEventTask state=finished event=on_ready coro=<bound method Bot.on_ready of <bot.bot.Bot object at 0x000001DE5E36CEE0>> exception=Forbidden('403 Forbidden (error code: 50001): Missing Access')>
Traceback (most recent call last):
  File "C:\Users\Vaishnav\.virtualenvs\Tortoise-BOT-NdGTmAqy\lib\site-packages\discord\client.py", line 312, in _run_event
    await coro(*args, **kwargs)
  File "C:\Users\Vaishnav\Projects\Tortoise-BOT\bot\bot.py", line 43, in on_ready
    await self.on_first_ready()
  File "C:\Users\Vaishnav\Projects\Tortoise-BOT\bot\bot.py", line 49, in on_first_ready
    await self.reload_tortoise_meta_cache()
  File "C:\Users\Vaishnav\Projects\Tortoise-BOT\bot\bot.py", line 55, in reload_tortoise_meta_cache
    self.tortoise_meta_cache = await self.api_client.get_server_meta()
  File "C:\Users\Vaishnav\Projects\Tortoise-BOT\bot\api_client.py", line 128, in get_server_meta
    return await self.get(f"server/meta/{guild_id}/")
  File "C:\Users\Vaishnav\Projects\Tortoise-BOT\bot\api_client.py", line 62, in get
    await self.raise_for_status(resp)
  File "C:\Users\Vaishnav\Projects\Tortoise-BOT\bot\api_client.py", line 55, in raise_for_status
    raise ResponseCodeError(response=response, response_json=response_json)
bot.api_client.ResponseCodeError: Status: 401 Response: {'detail': 'Invalid token.'}

During handling of the above exception, another exception occurred:

Traceback (most recent call last):
  File "C:\Users\Vaishnav\.virtualenvs\Tortoise-BOT-NdGTmAqy\lib\site-packages\discord\client.py", line 317, in _run_event
    await self.on_error(event_name, *args, **kwargs)
  File "C:\Users\Vaishnav\Projects\Tortoise-BOT\bot\bot.py", line 90, in on_error
    await self.log_error(msg)
  File "C:\Users\Vaishnav\Projects\Tortoise-BOT\bot\bot.py", line 101, in log_error
    await error_log_channel.send(f"```Num {count+1}/{len(split_messages)}:\n{message}```")
  File "C:\Users\Vaishnav\.virtualenvs\Tortoise-BOT-NdGTmAqy\lib\site-packages\discord\abc.py", line 870, in send
    data = await state.http.send_message(channel.id, content, tts=tts, embed=embed, nonce=nonce)
  File "C:\Users\Vaishnav\.virtualenvs\Tortoise-BOT-NdGTmAqy\lib\site-packages\discord\http.py", line 221, in request
    raise Forbidden(r, data)
discord.errors.Forbidden: 403 Forbidden (error code: 50001): Missing Access
2020-09-15 21:37:40,955 - discord.client - Received signal to terminate bot and event loop.
2020-09-15 21:37:40,955 - discord.client - Cleaning up tasks.
2020-09-15 21:37:40,956 - discord.client - Cleaning up after 4 tasks.
2020-09-15 21:37:41,544 - discord.client - All tasks finished cancelling.
2020-09-15 21:37:41,545 - discord.client - Closing the event loop.
2020-09-15 23:17:12,812 - discord.client - logging in using static token
2020-09-15 23:17:17,646 - discord.gateway - Created websocket connected to wss://gateway.discord.gg?encoding=json&v=6&compress=zlib-stream
2020-09-15 23:17:17,649 - discord.gateway - Shard ID None has sent the IDENTIFY payload.
2020-09-15 23:17:18,707 - discord.gateway - Shard ID None has connected to Gateway: ["gateway-prd-main-9h3r",{"micros":76638,"calls":["discord-sessions-prd-2-19",{"micros":69162,"calls":["start_session",{"micros":48306,"calls":["api-prd-main-jqgm",{"micros":45688,"calls":["get_user",{"micros":2684},"add_authorized_ip",{"micros":1555},"get_guilds",{"micros":5622},"coros_wait",{"micros":1}]}]},"guilds_connect",{"micros":22,"calls":[]},"presence_connect",{"micros":8301,"calls":[]}]}]}] (Session ID: eac16eabe99177b7ba7ea8eb7e8d1f74).
2020-09-15 23:17:18,716 - bot.bot - Connection to Discord established.
2020-09-15 23:17:27,262 - discord.state - Processed a chunk for 1000 members in guild ID 577192344529404154.
2020-09-15 23:17:27,860 - discord.state - Processed a chunk for 1000 members in guild ID 577192344529404154.
2020-09-15 23:17:27,870 - discord.state - Processed a chunk for 140 members in guild ID 577192344529404154.
2020-09-15 23:17:27,872 - console - Successfully logged in as gambling bot ID:729824279990108222 	d.py version: 1.3.4 	Further logging output will go to log file..
2020-09-15 23:17:27,944 - console - loaded bot.cogs.games
2020-09-15 23:17:37,223 - bot.bot - on_ready event error exception!
Traceback (most recent call last):
  File "C:\Users\Vaishnav\.virtualenvs\Tortoise-BOT-NdGTmAqy\lib\site-packages\discord\client.py", line 312, in _run_event
    await coro(*args, **kwargs)
  File "C:\Users\Vaishnav\Projects\Tortoise-BOT\bot\bot.py", line 43, in on_ready
    await self.on_first_ready()
  File "C:\Users\Vaishnav\Projects\Tortoise-BOT\bot\bot.py", line 49, in on_first_ready
    await self.reload_tortoise_meta_cache()
  File "C:\Users\Vaishnav\Projects\Tortoise-BOT\bot\bot.py", line 55, in reload_tortoise_meta_cache
    self.tortoise_meta_cache = await self.api_client.get_server_meta()
  File "C:\Users\Vaishnav\Projects\Tortoise-BOT\bot\api_client.py", line 128, in get_server_meta
    return await self.get(f"server/meta/{guild_id}/")
  File "C:\Users\Vaishnav\Projects\Tortoise-BOT\bot\api_client.py", line 62, in get
    await self.raise_for_status(resp)
  File "C:\Users\Vaishnav\Projects\Tortoise-BOT\bot\api_client.py", line 55, in raise_for_status
    raise ResponseCodeError(response=response, response_json=response_json)
bot.api_client.ResponseCodeError: Status: 401 Response: {'detail': 'Invalid token.'}

2020-09-15 23:17:40,093 - asyncio - _ClientEventTask exception was never retrieved
future: <ClientEventTask state=finished event=on_ready coro=<bound method Bot.on_ready of <bot.bot.Bot object at 0x000001ED215FCEE0>> exception=Forbidden('403 Forbidden (error code: 50001): Missing Access')>
Traceback (most recent call last):
  File "C:\Users\Vaishnav\.virtualenvs\Tortoise-BOT-NdGTmAqy\lib\site-packages\discord\client.py", line 312, in _run_event
    await coro(*args, **kwargs)
  File "C:\Users\Vaishnav\Projects\Tortoise-BOT\bot\bot.py", line 43, in on_ready
    await self.on_first_ready()
  File "C:\Users\Vaishnav\Projects\Tortoise-BOT\bot\bot.py", line 49, in on_first_ready
    await self.reload_tortoise_meta_cache()
  File "C:\Users\Vaishnav\Projects\Tortoise-BOT\bot\bot.py", line 55, in reload_tortoise_meta_cache
    self.tortoise_meta_cache = await self.api_client.get_server_meta()
  File "C:\Users\Vaishnav\Projects\Tortoise-BOT\bot\api_client.py", line 128, in get_server_meta
    return await self.get(f"server/meta/{guild_id}/")
  File "C:\Users\Vaishnav\Projects\Tortoise-BOT\bot\api_client.py", line 62, in get
    await self.raise_for_status(resp)
  File "C:\Users\Vaishnav\Projects\Tortoise-BOT\bot\api_client.py", line 55, in raise_for_status
    raise ResponseCodeError(response=response, response_json=response_json)
bot.api_client.ResponseCodeError: Status: 401 Response: {'detail': 'Invalid token.'}

During handling of the above exception, another exception occurred:

Traceback (most recent call last):
  File "C:\Users\Vaishnav\.virtualenvs\Tortoise-BOT-NdGTmAqy\lib\site-packages\discord\client.py", line 317, in _run_event
    await self.on_error(event_name, *args, **kwargs)
  File "C:\Users\Vaishnav\Projects\Tortoise-BOT\bot\bot.py", line 90, in on_error
    await self.log_error(msg)
  File "C:\Users\Vaishnav\Projects\Tortoise-BOT\bot\bot.py", line 101, in log_error
    await error_log_channel.send(f"```Num {count+1}/{len(split_messages)}:\n{message}```")
  File "C:\Users\Vaishnav\.virtualenvs\Tortoise-BOT-NdGTmAqy\lib\site-packages\discord\abc.py", line 870, in send
    data = await state.http.send_message(channel.id, content, tts=tts, embed=embed, nonce=nonce)
  File "C:\Users\Vaishnav\.virtualenvs\Tortoise-BOT-NdGTmAqy\lib\site-packages\discord\http.py", line 221, in request
    raise Forbidden(r, data)
discord.errors.Forbidden: 403 Forbidden (error code: 50001): Missing Access
2020-09-15 23:24:23,840 - discord.client - Received signal to terminate bot and event loop.
2020-09-15 23:24:23,840 - discord.client - Cleaning up tasks.
2020-09-15 23:24:23,840 - discord.client - Cleaning up after 4 tasks.
2020-09-15 23:24:24,074 - discord.client - Closing the event loop.
2020-09-17 00:06:39,194 - discord.client - logging in using static token
2020-09-17 00:06:42,681 - discord.gateway - Created websocket connected to wss://gateway.discord.gg?encoding=json&v=6&compress=zlib-stream
2020-09-17 00:06:42,684 - discord.gateway - Shard ID None has sent the IDENTIFY payload.
2020-09-17 00:06:43,589 - discord.gateway - Shard ID None has connected to Gateway: ["gateway-prd-main-03dm",{"micros":40123,"calls":["discord-sessions-prd-2-8",{"micros":37406,"calls":["start_session",{"micros":33792,"calls":["api-prd-main-t2fh",{"micros":30966,"calls":["get_user",{"micros":4754},"add_authorized_ip",{"micros":1550},"get_guilds",{"micros":2419},"coros_wait",{"micros":1}]}]},"guilds_connect",{"micros":4,"calls":[]},"presence_connect",{"micros":1,"calls":[]}]}]}] (Session ID: 1e62c10668a8b655852191a38f1e1aea).
2020-09-17 00:06:43,598 - bot.bot - Connection to Discord established.
2020-09-17 00:06:47,187 - discord.state - Processed a chunk for 1000 members in guild ID 577192344529404154.
2020-09-17 00:06:47,256 - discord.state - Processed a chunk for 1000 members in guild ID 577192344529404154.
2020-09-17 00:06:47,260 - discord.state - Processed a chunk for 144 members in guild ID 577192344529404154.
2020-09-17 00:06:47,261 - console - Successfully logged in as gambling bot ID:729824279990108222 	d.py version: 1.3.4 	Further logging output will go to log file..
2020-09-17 00:06:47,303 - console - loaded bot.cogs.bot_owner_commands
2020-09-17 00:06:47,314 - console - loaded bot.cogs.cmd_error_handler
2020-09-17 00:06:47,321 - console - loaded bot.cogs.documentation
2020-09-17 00:06:47,330 - console - loaded bot.cogs.fun
2020-09-17 00:06:47,341 - console - loaded bot.cogs.games
2020-09-17 00:06:47,357 - console - loaded bot.cogs.help
2020-09-17 00:06:47,383 - console - loaded bot.cogs.moderation
2020-09-17 00:06:48,435 - console - loaded bot.cogs.music
2020-09-17 00:06:48,486 - console - loaded bot.cogs.other
2020-09-17 00:06:48,761 - console - Failed to load cog bot.cogs.reddit - traceback:['Traceback (most recent call last):\n', '  File "C:\\Users\\Vaishnav\\.virtualenvs\\Tortoise-BOT-NdGTmAqy\\lib\\site-packages\\discord\\ext\\commands\\bot.py", line 608, in _load_from_module_spec\n    setup(self)\n', '  File "C:\\Users\\Vaishnav\\Projects\\Tortoise-BOT\\bot\\cogs\\reddit.py", line 48, in setup\n    bot.add_cog(Reddit(bot))\n', '  File "C:\\Users\\Vaishnav\\Projects\\Tortoise-BOT\\bot\\cogs\\reddit.py", line 13, in __init__\n    self.reddit = praw.Reddit(\n', '  File "C:\\Users\\Vaishnav\\.virtualenvs\\Tortoise-BOT-NdGTmAqy\\lib\\site-packages\\praw\\reddit.py", line 221, in __init__\n    raise MissingRequiredAttributeException(\n', "praw.exceptions.MissingRequiredAttributeException: Required configuration setting 'client_id' missing. \nThis setting can be provided in a praw.ini file, as a keyword argument to the `Reddit` class constructor, or as an environment variable.\n", '\nThe above exception was the direct cause of the following exception:\n\n', 'Traceback (most recent call last):\n', '  File "C:\\Users\\Vaishnav\\Projects\\Tortoise-BOT\\bot\\bot.py", line 69, in load_extensions\n    self.load_extension(dotted_path)\n', '  File "C:\\Users\\Vaishnav\\.virtualenvs\\Tortoise-BOT-NdGTmAqy\\lib\\site-packages\\discord\\ext\\commands\\bot.py", line 653, in load_extension\n    self._load_from_module_spec(spec, name)\n', '  File "C:\\Users\\Vaishnav\\.virtualenvs\\Tortoise-BOT-NdGTmAqy\\lib\\site-packages\\discord\\ext\\commands\\bot.py", line 613, in _load_from_module_spec\n    raise errors.ExtensionFailed(key, e) from e\n', "discord.ext.commands.errors.ExtensionFailed: Extension 'bot.cogs.reddit' raised an error: MissingRequiredAttributeException: Required configuration setting 'client_id' missing. \nThis setting can be provided in a praw.ini file, as a keyword argument to the `Reddit` class constructor, or as an environment variable.\n"]
2020-09-17 00:06:48,781 - console - loaded bot.cogs.security
2020-09-17 00:06:48,792 - bot.cogs.socket_comm - Starting socket comm server...
2020-09-17 00:06:48,793 - console - Failed to load cog bot.cogs.socket_comm - traceback:['Traceback (most recent call last):\n', '  File "C:\\Users\\Vaishnav\\.virtualenvs\\Tortoise-BOT-NdGTmAqy\\lib\\site-packages\\discord\\ext\\commands\\bot.py", line 608, in _load_from_module_spec\n    setup(self)\n', '  File "C:\\Users\\Vaishnav\\Projects\\Tortoise-BOT\\bot\\cogs\\socket_comm.py", line 420, in setup\n    bot.add_cog(SocketCommunication(bot))\n', '  File "C:\\Users\\Vaishnav\\Projects\\Tortoise-BOT\\bot\\cogs\\socket_comm.py", line 86, in __init__\n    self._socket_server = SocketCommunication.create_server()\n', '  File "C:\\Users\\Vaishnav\\Projects\\Tortoise-BOT\\bot\\cogs\\socket_comm.py", line 119, in create_server\n    server.bind(("0.0.0.0", int(os.getenv("SOCKET_SERVER_PORT"))))\n', "TypeError: int() argument must be a string, a bytes-like object or a number, not 'NoneType'\n", '\nThe above exception was the direct cause of the following exception:\n\n', 'Traceback (most recent call last):\n', '  File "C:\\Users\\Vaishnav\\Projects\\Tortoise-BOT\\bot\\bot.py", line 69, in load_extensions\n    self.load_extension(dotted_path)\n', '  File "C:\\Users\\Vaishnav\\.virtualenvs\\Tortoise-BOT-NdGTmAqy\\lib\\site-packages\\discord\\ext\\commands\\bot.py", line 653, in load_extension\n    self._load_from_module_spec(spec, name)\n', '  File "C:\\Users\\Vaishnav\\.virtualenvs\\Tortoise-BOT-NdGTmAqy\\lib\\site-packages\\discord\\ext\\commands\\bot.py", line 613, in _load_from_module_spec\n    raise errors.ExtensionFailed(key, e) from e\n', "discord.ext.commands.errors.ExtensionFailed: Extension 'bot.cogs.socket_comm' raised an error: TypeError: int() argument must be a string, a bytes-like object or a number, not 'NoneType'\n"]
2020-09-17 00:06:48,802 - console - loaded bot.cogs.tortoise_api
2020-09-17 00:06:48,826 - console - loaded bot.cogs.tortoise_dm
2020-09-17 00:06:48,838 - console - loaded bot.cogs.tortoise_server
2020-09-17 00:06:50,712 - bot.cogs.tortoise_server - Failed to fetch rules from API:Status: 401 Response: {'detail': 'Invalid token.'}
2020-09-17 00:06:52,946 - bot.bot - on_ready event error exception!
Traceback (most recent call last):
  File "C:\Users\Vaishnav\.virtualenvs\Tortoise-BOT-NdGTmAqy\lib\site-packages\discord\client.py", line 312, in _run_event
    await coro(*args, **kwargs)
  File "C:\Users\Vaishnav\Projects\Tortoise-BOT\bot\bot.py", line 43, in on_ready
    await self.on_first_ready()
  File "C:\Users\Vaishnav\Projects\Tortoise-BOT\bot\bot.py", line 49, in on_first_ready
    await self.reload_tortoise_meta_cache()
  File "C:\Users\Vaishnav\Projects\Tortoise-BOT\bot\bot.py", line 55, in reload_tortoise_meta_cache
    self.tortoise_meta_cache = await self.api_client.get_server_meta()
  File "C:\Users\Vaishnav\Projects\Tortoise-BOT\bot\api_client.py", line 128, in get_server_meta
    return await self.get(f"server/meta/{guild_id}/")
  File "C:\Users\Vaishnav\Projects\Tortoise-BOT\bot\api_client.py", line 62, in get
    await self.raise_for_status(resp)
  File "C:\Users\Vaishnav\Projects\Tortoise-BOT\bot\api_client.py", line 55, in raise_for_status
    raise ResponseCodeError(response=response, response_json=response_json)
bot.api_client.ResponseCodeError: Status: 401 Response: {'detail': 'Invalid token.'}

2020-09-17 00:06:53,676 - asyncio - _ClientEventTask exception was never retrieved
future: <ClientEventTask state=finished event=on_ready coro=<bound method Bot.on_ready of <bot.bot.Bot object at 0x000001D88C40AEE0>> exception=Forbidden('403 Forbidden (error code: 50001): Missing Access')>
Traceback (most recent call last):
  File "C:\Users\Vaishnav\.virtualenvs\Tortoise-BOT-NdGTmAqy\lib\site-packages\discord\client.py", line 312, in _run_event
    await coro(*args, **kwargs)
  File "C:\Users\Vaishnav\Projects\Tortoise-BOT\bot\bot.py", line 43, in on_ready
    await self.on_first_ready()
  File "C:\Users\Vaishnav\Projects\Tortoise-BOT\bot\bot.py", line 49, in on_first_ready
    await self.reload_tortoise_meta_cache()
  File "C:\Users\Vaishnav\Projects\Tortoise-BOT\bot\bot.py", line 55, in reload_tortoise_meta_cache
    self.tortoise_meta_cache = await self.api_client.get_server_meta()
  File "C:\Users\Vaishnav\Projects\Tortoise-BOT\bot\api_client.py", line 128, in get_server_meta
    return await self.get(f"server/meta/{guild_id}/")
  File "C:\Users\Vaishnav\Projects\Tortoise-BOT\bot\api_client.py", line 62, in get
    await self.raise_for_status(resp)
  File "C:\Users\Vaishnav\Projects\Tortoise-BOT\bot\api_client.py", line 55, in raise_for_status
    raise ResponseCodeError(response=response, response_json=response_json)
bot.api_client.ResponseCodeError: Status: 401 Response: {'detail': 'Invalid token.'}

During handling of the above exception, another exception occurred:

Traceback (most recent call last):
  File "C:\Users\Vaishnav\.virtualenvs\Tortoise-BOT-NdGTmAqy\lib\site-packages\discord\client.py", line 317, in _run_event
    await self.on_error(event_name, *args, **kwargs)
  File "C:\Users\Vaishnav\Projects\Tortoise-BOT\bot\bot.py", line 90, in on_error
    await self.log_error(msg)
  File "C:\Users\Vaishnav\Projects\Tortoise-BOT\bot\bot.py", line 101, in log_error
    await error_log_channel.send(f"```Num {count+1}/{len(split_messages)}:\n{message}```")
  File "C:\Users\Vaishnav\.virtualenvs\Tortoise-BOT-NdGTmAqy\lib\site-packages\discord\abc.py", line 870, in send
    data = await state.http.send_message(channel.id, content, tts=tts, embed=embed, nonce=nonce)
  File "C:\Users\Vaishnav\.virtualenvs\Tortoise-BOT-NdGTmAqy\lib\site-packages\discord\http.py", line 221, in request
    raise Forbidden(r, data)
discord.errors.Forbidden: 403 Forbidden (error code: 50001): Missing Access
2020-09-17 00:06:53,794 - bot.cogs.tortoise_server - Failed to fetch rules from API:Status: 401 Response: {'detail': 'Invalid token.'}
2020-09-17 00:06:56,313 - bot.cogs.tortoise_server - Failed to fetch rules from API:Status: 401 Response: {'detail': 'Invalid token.'}
2020-09-17 00:07:00,495 - bot.cogs.tortoise_server - Failed to fetch rules from API:Status: 401 Response: {'detail': 'Invalid token.'}
2020-09-17 00:07:05,277 - discord.client - Received signal to terminate bot and event loop.
2020-09-17 00:07:05,277 - discord.client - Cleaning up tasks.
2020-09-17 00:07:05,277 - discord.client - Cleaning up after 7 tasks.
2020-09-17 00:07:05,291 - asyncio - Unclosed client session
client_session: <aiohttp.client.ClientSession object at 0x000001D88E032850>
2020-09-17 00:07:05,460 - discord.client - Closing the event loop.
2020-09-17 00:08:18,015 - discord.client - logging in using static token
2020-09-17 00:08:22,589 - discord.gateway - Created websocket connected to wss://gateway.discord.gg?encoding=json&v=6&compress=zlib-stream
2020-09-17 00:08:22,594 - discord.gateway - Shard ID None has sent the IDENTIFY payload.
2020-09-17 00:08:23,667 - discord.gateway - Shard ID None has connected to Gateway: ["gateway-prd-main-0cct",{"micros":120293,"calls":["discord-sessions-prd-2-85",{"micros":118188,"calls":["start_session",{"micros":106239,"calls":["api-prd-main-r8f0",{"micros":102623,"calls":["get_user",{"micros":5469},"add_authorized_ip",{"micros":13945},"get_guilds",{"micros":9840},"coros_wait",{"micros":2}]}]},"guilds_connect",{"micros":6,"calls":[]},"presence_connect",{"micros":7765,"calls":[]}]}]}] (Session ID: e97a7cc7de22346605b9b0268481f392).
2020-09-17 00:08:23,682 - bot.bot - Connection to Discord established.
2020-09-17 00:08:27,975 - discord.state - Processed a chunk for 1000 members in guild ID 577192344529404154.
2020-09-17 00:08:28,133 - discord.state - Processed a chunk for 1000 members in guild ID 577192344529404154.
2020-09-17 00:08:28,138 - discord.state - Processed a chunk for 144 members in guild ID 577192344529404154.
2020-09-17 00:08:28,138 - console - Successfully logged in as gambling bot ID:729824279990108222 	d.py version: 1.3.4 	Further logging output will go to log file..
2020-09-17 00:08:28,148 - console - loaded bot.cogs.games
2020-09-17 00:08:32,540 - bot.bot - on_ready event error exception!
Traceback (most recent call last):
  File "C:\Users\Vaishnav\.virtualenvs\Tortoise-BOT-NdGTmAqy\lib\site-packages\discord\client.py", line 312, in _run_event
    await coro(*args, **kwargs)
  File "C:\Users\Vaishnav\Projects\Tortoise-BOT\bot\bot.py", line 43, in on_ready
    await self.on_first_ready()
  File "C:\Users\Vaishnav\Projects\Tortoise-BOT\bot\bot.py", line 49, in on_first_ready
    await self.reload_tortoise_meta_cache()
  File "C:\Users\Vaishnav\Projects\Tortoise-BOT\bot\bot.py", line 55, in reload_tortoise_meta_cache
    self.tortoise_meta_cache = await self.api_client.get_server_meta()
  File "C:\Users\Vaishnav\Projects\Tortoise-BOT\bot\api_client.py", line 128, in get_server_meta
    return await self.get(f"server/meta/{guild_id}/")
  File "C:\Users\Vaishnav\Projects\Tortoise-BOT\bot\api_client.py", line 62, in get
    await self.raise_for_status(resp)
  File "C:\Users\Vaishnav\Projects\Tortoise-BOT\bot\api_client.py", line 55, in raise_for_status
    raise ResponseCodeError(response=response, response_json=response_json)
bot.api_client.ResponseCodeError: Status: 401 Response: {'detail': 'Invalid token.'}

2020-09-17 00:08:33,202 - asyncio - _ClientEventTask exception was never retrieved
future: <ClientEventTask state=finished event=on_ready coro=<bound method Bot.on_ready of <bot.bot.Bot object at 0x000002A4751A8FD0>> exception=Forbidden('403 Forbidden (error code: 50001): Missing Access')>
Traceback (most recent call last):
  File "C:\Users\Vaishnav\.virtualenvs\Tortoise-BOT-NdGTmAqy\lib\site-packages\discord\client.py", line 312, in _run_event
    await coro(*args, **kwargs)
  File "C:\Users\Vaishnav\Projects\Tortoise-BOT\bot\bot.py", line 43, in on_ready
    await self.on_first_ready()
  File "C:\Users\Vaishnav\Projects\Tortoise-BOT\bot\bot.py", line 49, in on_first_ready
    await self.reload_tortoise_meta_cache()
  File "C:\Users\Vaishnav\Projects\Tortoise-BOT\bot\bot.py", line 55, in reload_tortoise_meta_cache
    self.tortoise_meta_cache = await self.api_client.get_server_meta()
  File "C:\Users\Vaishnav\Projects\Tortoise-BOT\bot\api_client.py", line 128, in get_server_meta
    return await self.get(f"server/meta/{guild_id}/")
  File "C:\Users\Vaishnav\Projects\Tortoise-BOT\bot\api_client.py", line 62, in get
    await self.raise_for_status(resp)
  File "C:\Users\Vaishnav\Projects\Tortoise-BOT\bot\api_client.py", line 55, in raise_for_status
    raise ResponseCodeError(response=response, response_json=response_json)
bot.api_client.ResponseCodeError: Status: 401 Response: {'detail': 'Invalid token.'}

During handling of the above exception, another exception occurred:

Traceback (most recent call last):
  File "C:\Users\Vaishnav\.virtualenvs\Tortoise-BOT-NdGTmAqy\lib\site-packages\discord\client.py", line 317, in _run_event
    await self.on_error(event_name, *args, **kwargs)
  File "C:\Users\Vaishnav\Projects\Tortoise-BOT\bot\bot.py", line 90, in on_error
    await self.log_error(msg)
  File "C:\Users\Vaishnav\Projects\Tortoise-BOT\bot\bot.py", line 101, in log_error
    await error_log_channel.send(f"```Num {count+1}/{len(split_messages)}:\n{message}```")
  File "C:\Users\Vaishnav\.virtualenvs\Tortoise-BOT-NdGTmAqy\lib\site-packages\discord\abc.py", line 870, in send
    data = await state.http.send_message(channel.id, content, tts=tts, embed=embed, nonce=nonce)
  File "C:\Users\Vaishnav\.virtualenvs\Tortoise-BOT-NdGTmAqy\lib\site-packages\discord\http.py", line 221, in request
    raise Forbidden(r, data)
discord.errors.Forbidden: 403 Forbidden (error code: 50001): Missing Access
2020-09-17 00:12:41,053 - discord.client - Received signal to terminate bot and event loop.
2020-09-17 00:12:41,054 - discord.client - Cleaning up tasks.
2020-09-17 00:12:41,054 - discord.client - Cleaning up after 4 tasks.
2020-09-17 00:12:41,724 - discord.client - Closing the event loop.
2020-09-17 00:12:48,161 - discord.client - logging in using static token
2020-09-17 00:12:51,986 - discord.gateway - Created websocket connected to wss://gateway.discord.gg?encoding=json&v=6&compress=zlib-stream
2020-09-17 00:12:51,989 - discord.gateway - Shard ID None has sent the IDENTIFY payload.
2020-09-17 00:12:53,052 - discord.gateway - Shard ID None has connected to Gateway: ["gateway-prd-main-z971",{"micros":121003,"calls":["discord-sessions-prd-1-16",{"micros":60274,"calls":["start_session",{"micros":50783,"calls":["api-prd-main-4xj0",{"micros":47981,"calls":["get_user",{"micros":3560},"add_authorized_ip",{"micros":2434},"get_guilds",{"micros":2943},"coros_wait",{"micros":1}]}]},"guilds_connect",{"micros":3,"calls":[]},"presence_connect",{"micros":1,"calls":[]}]}]}] (Session ID: a4c784705fdf2c2dcdbd5de352f56bd0).
2020-09-17 00:12:53,065 - bot.bot - Connection to Discord established.
2020-09-17 00:12:56,671 - discord.state - Processed a chunk for 1000 members in guild ID 577192344529404154.
2020-09-17 00:12:56,743 - discord.state - Processed a chunk for 1000 members in guild ID 577192344529404154.
2020-09-17 00:12:56,747 - discord.state - Processed a chunk for 144 members in guild ID 577192344529404154.
2020-09-17 00:12:56,748 - console - Successfully logged in as gambling bot ID:729824279990108222 	d.py version: 1.3.4 	Further logging output will go to log file..
2020-09-17 00:12:56,755 - console - loaded bot.cogs.games
2020-09-17 00:13:01,320 - bot.bot - on_ready event error exception!
Traceback (most recent call last):
  File "C:\Users\Vaishnav\.virtualenvs\Tortoise-BOT-NdGTmAqy\lib\site-packages\discord\client.py", line 312, in _run_event
    await coro(*args, **kwargs)
  File "C:\Users\Vaishnav\Projects\Tortoise-BOT\bot\bot.py", line 43, in on_ready
    await self.on_first_ready()
  File "C:\Users\Vaishnav\Projects\Tortoise-BOT\bot\bot.py", line 49, in on_first_ready
    await self.reload_tortoise_meta_cache()
  File "C:\Users\Vaishnav\Projects\Tortoise-BOT\bot\bot.py", line 55, in reload_tortoise_meta_cache
    self.tortoise_meta_cache = await self.api_client.get_server_meta()
  File "C:\Users\Vaishnav\Projects\Tortoise-BOT\bot\api_client.py", line 128, in get_server_meta
    return await self.get(f"server/meta/{guild_id}/")
  File "C:\Users\Vaishnav\Projects\Tortoise-BOT\bot\api_client.py", line 62, in get
    await self.raise_for_status(resp)
  File "C:\Users\Vaishnav\Projects\Tortoise-BOT\bot\api_client.py", line 55, in raise_for_status
    raise ResponseCodeError(response=response, response_json=response_json)
bot.api_client.ResponseCodeError: Status: 401 Response: {'detail': 'Invalid token.'}

2020-09-17 00:13:01,981 - asyncio - _ClientEventTask exception was never retrieved
future: <ClientEventTask state=finished event=on_ready coro=<bound method Bot.on_ready of <bot.bot.Bot object at 0x000001EAA981AF10>> exception=Forbidden('403 Forbidden (error code: 50001): Missing Access')>
Traceback (most recent call last):
  File "C:\Users\Vaishnav\.virtualenvs\Tortoise-BOT-NdGTmAqy\lib\site-packages\discord\client.py", line 312, in _run_event
    await coro(*args, **kwargs)
  File "C:\Users\Vaishnav\Projects\Tortoise-BOT\bot\bot.py", line 43, in on_ready
    await self.on_first_ready()
  File "C:\Users\Vaishnav\Projects\Tortoise-BOT\bot\bot.py", line 49, in on_first_ready
    await self.reload_tortoise_meta_cache()
  File "C:\Users\Vaishnav\Projects\Tortoise-BOT\bot\bot.py", line 55, in reload_tortoise_meta_cache
    self.tortoise_meta_cache = await self.api_client.get_server_meta()
  File "C:\Users\Vaishnav\Projects\Tortoise-BOT\bot\api_client.py", line 128, in get_server_meta
    return await self.get(f"server/meta/{guild_id}/")
  File "C:\Users\Vaishnav\Projects\Tortoise-BOT\bot\api_client.py", line 62, in get
    await self.raise_for_status(resp)
  File "C:\Users\Vaishnav\Projects\Tortoise-BOT\bot\api_client.py", line 55, in raise_for_status
    raise ResponseCodeError(response=response, response_json=response_json)
bot.api_client.ResponseCodeError: Status: 401 Response: {'detail': 'Invalid token.'}

During handling of the above exception, another exception occurred:

Traceback (most recent call last):
  File "C:\Users\Vaishnav\.virtualenvs\Tortoise-BOT-NdGTmAqy\lib\site-packages\discord\client.py", line 317, in _run_event
    await self.on_error(event_name, *args, **kwargs)
  File "C:\Users\Vaishnav\Projects\Tortoise-BOT\bot\bot.py", line 90, in on_error
    await self.log_error(msg)
  File "C:\Users\Vaishnav\Projects\Tortoise-BOT\bot\bot.py", line 101, in log_error
    await error_log_channel.send(f"```Num {count+1}/{len(split_messages)}:\n{message}```")
  File "C:\Users\Vaishnav\.virtualenvs\Tortoise-BOT-NdGTmAqy\lib\site-packages\discord\abc.py", line 870, in send
    data = await state.http.send_message(channel.id, content, tts=tts, embed=embed, nonce=nonce)
  File "C:\Users\Vaishnav\.virtualenvs\Tortoise-BOT-NdGTmAqy\lib\site-packages\discord\http.py", line 221, in request
    raise Forbidden(r, data)
discord.errors.Forbidden: 403 Forbidden (error code: 50001): Missing Access
2020-09-17 00:14:15,980 - discord.client - Received signal to terminate bot and event loop.
2020-09-17 00:14:15,981 - discord.client - Cleaning up tasks.
2020-09-17 00:14:15,981 - discord.client - Cleaning up after 4 tasks.
2020-09-17 00:14:16,204 - discord.client - Closing the event loop.
2020-09-17 00:14:21,324 - discord.client - logging in using static token
2020-09-17 00:14:24,901 - discord.gateway - Created websocket connected to wss://gateway.discord.gg?encoding=json&v=6&compress=zlib-stream
2020-09-17 00:14:24,904 - discord.gateway - Shard ID None has sent the IDENTIFY payload.
2020-09-17 00:14:25,886 - discord.gateway - Shard ID None has connected to Gateway: ["gateway-prd-main-khp7",{"micros":70244,"calls":["discord-sessions-prd-2-60",{"micros":65914,"calls":["start_session",{"micros":45375,"calls":["api-prd-main-w1s2",{"micros":42057,"calls":["get_user",{"micros":2705},"add_authorized_ip",{"micros":1638},"get_guilds",{"micros":1223},"coros_wait",{"micros":0}]}]},"guilds_connect",{"micros":3,"calls":[]},"presence_connect",{"micros":9208,"calls":[]}]}]}] (Session ID: 30a4aaf2505d91061701f58615b29181).
2020-09-17 00:14:25,902 - bot.bot - Connection to Discord established.
2020-09-17 00:14:29,773 - discord.state - Processed a chunk for 1000 members in guild ID 577192344529404154.
2020-09-17 00:14:29,845 - discord.state - Processed a chunk for 1000 members in guild ID 577192344529404154.
2020-09-17 00:14:29,850 - discord.state - Processed a chunk for 144 members in guild ID 577192344529404154.
2020-09-17 00:14:29,850 - console - Successfully logged in as gambling bot ID:729824279990108222 	d.py version: 1.3.4 	Further logging output will go to log file..
2020-09-17 00:14:29,859 - console - loaded bot.cogs.games
2020-09-17 00:14:34,313 - bot.bot - on_ready event error exception!
Traceback (most recent call last):
  File "C:\Users\Vaishnav\.virtualenvs\Tortoise-BOT-NdGTmAqy\lib\site-packages\discord\client.py", line 312, in _run_event
    await coro(*args, **kwargs)
  File "C:\Users\Vaishnav\Projects\Tortoise-BOT\bot\bot.py", line 43, in on_ready
    await self.on_first_ready()
  File "C:\Users\Vaishnav\Projects\Tortoise-BOT\bot\bot.py", line 49, in on_first_ready
    await self.reload_tortoise_meta_cache()
  File "C:\Users\Vaishnav\Projects\Tortoise-BOT\bot\bot.py", line 55, in reload_tortoise_meta_cache
    self.tortoise_meta_cache = await self.api_client.get_server_meta()
  File "C:\Users\Vaishnav\Projects\Tortoise-BOT\bot\api_client.py", line 128, in get_server_meta
    return await self.get(f"server/meta/{guild_id}/")
  File "C:\Users\Vaishnav\Projects\Tortoise-BOT\bot\api_client.py", line 62, in get
    await self.raise_for_status(resp)
  File "C:\Users\Vaishnav\Projects\Tortoise-BOT\bot\api_client.py", line 55, in raise_for_status
    raise ResponseCodeError(response=response, response_json=response_json)
bot.api_client.ResponseCodeError: Status: 401 Response: {'detail': 'Invalid token.'}

2020-09-17 00:14:35,018 - asyncio - _ClientEventTask exception was never retrieved
future: <ClientEventTask state=finished event=on_ready coro=<bound method Bot.on_ready of <bot.bot.Bot object at 0x0000026F8D1B8E50>> exception=Forbidden('403 Forbidden (error code: 50001): Missing Access')>
Traceback (most recent call last):
  File "C:\Users\Vaishnav\.virtualenvs\Tortoise-BOT-NdGTmAqy\lib\site-packages\discord\client.py", line 312, in _run_event
    await coro(*args, **kwargs)
  File "C:\Users\Vaishnav\Projects\Tortoise-BOT\bot\bot.py", line 43, in on_ready
    await self.on_first_ready()
  File "C:\Users\Vaishnav\Projects\Tortoise-BOT\bot\bot.py", line 49, in on_first_ready
    await self.reload_tortoise_meta_cache()
  File "C:\Users\Vaishnav\Projects\Tortoise-BOT\bot\bot.py", line 55, in reload_tortoise_meta_cache
    self.tortoise_meta_cache = await self.api_client.get_server_meta()
  File "C:\Users\Vaishnav\Projects\Tortoise-BOT\bot\api_client.py", line 128, in get_server_meta
    return await self.get(f"server/meta/{guild_id}/")
  File "C:\Users\Vaishnav\Projects\Tortoise-BOT\bot\api_client.py", line 62, in get
    await self.raise_for_status(resp)
  File "C:\Users\Vaishnav\Projects\Tortoise-BOT\bot\api_client.py", line 55, in raise_for_status
    raise ResponseCodeError(response=response, response_json=response_json)
bot.api_client.ResponseCodeError: Status: 401 Response: {'detail': 'Invalid token.'}

During handling of the above exception, another exception occurred:

Traceback (most recent call last):
  File "C:\Users\Vaishnav\.virtualenvs\Tortoise-BOT-NdGTmAqy\lib\site-packages\discord\client.py", line 317, in _run_event
    await self.on_error(event_name, *args, **kwargs)
  File "C:\Users\Vaishnav\Projects\Tortoise-BOT\bot\bot.py", line 90, in on_error
    await self.log_error(msg)
  File "C:\Users\Vaishnav\Projects\Tortoise-BOT\bot\bot.py", line 101, in log_error
    await error_log_channel.send(f"```Num {count+1}/{len(split_messages)}:\n{message}```")
  File "C:\Users\Vaishnav\.virtualenvs\Tortoise-BOT-NdGTmAqy\lib\site-packages\discord\abc.py", line 870, in send
    data = await state.http.send_message(channel.id, content, tts=tts, embed=embed, nonce=nonce)
  File "C:\Users\Vaishnav\.virtualenvs\Tortoise-BOT-NdGTmAqy\lib\site-packages\discord\http.py", line 221, in request
    raise Forbidden(r, data)
discord.errors.Forbidden: 403 Forbidden (error code: 50001): Missing Access
2020-09-17 00:18:00,058 - discord.client - Received signal to terminate bot and event loop.
2020-09-17 00:18:00,058 - discord.client - Cleaning up tasks.
2020-09-17 00:18:00,058 - discord.client - Cleaning up after 4 tasks.
2020-09-17 00:18:00,267 - discord.client - Closing the event loop.
2020-09-17 00:18:05,657 - discord.client - logging in using static token
2020-09-17 00:18:09,575 - discord.gateway - Created websocket connected to wss://gateway.discord.gg?encoding=json&v=6&compress=zlib-stream
2020-09-17 00:18:09,576 - discord.gateway - Shard ID None has sent the IDENTIFY payload.
2020-09-17 00:18:10,609 - discord.gateway - Shard ID None has connected to Gateway: ["gateway-prd-main-fbtr",{"micros":60826,"calls":["discord-sessions-prd-2-59",{"micros":56661,"calls":["start_session",{"micros":37816,"calls":["api-prd-main-jlxb",{"micros":34817,"calls":["get_user",{"micros":2802},"add_authorized_ip",{"micros":1500},"get_guilds",{"micros":1847},"coros_wait",{"micros":1}]}]},"guilds_connect",{"micros":3,"calls":[]},"presence_connect",{"micros":10415,"calls":[]}]}]}] (Session ID: 2c6f90b24bd4912e399b782d5725dd2a).
2020-09-17 00:18:10,622 - bot.bot - Connection to Discord established.
2020-09-17 00:18:14,207 - discord.state - Processed a chunk for 1000 members in guild ID 577192344529404154.
2020-09-17 00:18:14,322 - discord.state - Processed a chunk for 1000 members in guild ID 577192344529404154.
2020-09-17 00:18:14,326 - discord.state - Processed a chunk for 144 members in guild ID 577192344529404154.
2020-09-17 00:18:14,327 - console - Successfully logged in as gambling bot ID:729824279990108222 	d.py version: 1.3.4 	Further logging output will go to log file..
2020-09-17 00:18:14,334 - console - loaded bot.cogs.games
2020-09-17 00:18:19,660 - bot.bot - on_ready event error exception!
Traceback (most recent call last):
  File "C:\Users\Vaishnav\.virtualenvs\Tortoise-BOT-NdGTmAqy\lib\site-packages\discord\client.py", line 312, in _run_event
    await coro(*args, **kwargs)
  File "C:\Users\Vaishnav\Projects\Tortoise-BOT\bot\bot.py", line 43, in on_ready
    await self.on_first_ready()
  File "C:\Users\Vaishnav\Projects\Tortoise-BOT\bot\bot.py", line 49, in on_first_ready
    await self.reload_tortoise_meta_cache()
  File "C:\Users\Vaishnav\Projects\Tortoise-BOT\bot\bot.py", line 55, in reload_tortoise_meta_cache
    self.tortoise_meta_cache = await self.api_client.get_server_meta()
  File "C:\Users\Vaishnav\Projects\Tortoise-BOT\bot\api_client.py", line 128, in get_server_meta
    return await self.get(f"server/meta/{guild_id}/")
  File "C:\Users\Vaishnav\Projects\Tortoise-BOT\bot\api_client.py", line 62, in get
    await self.raise_for_status(resp)
  File "C:\Users\Vaishnav\Projects\Tortoise-BOT\bot\api_client.py", line 55, in raise_for_status
    raise ResponseCodeError(response=response, response_json=response_json)
bot.api_client.ResponseCodeError: Status: 401 Response: {'detail': 'Invalid token.'}

2020-09-17 00:18:20,382 - asyncio - _ClientEventTask exception was never retrieved
future: <ClientEventTask state=finished event=on_ready coro=<bound method Bot.on_ready of <bot.bot.Bot object at 0x000002BEA8338C70>> exception=Forbidden('403 Forbidden (error code: 50001): Missing Access')>
Traceback (most recent call last):
  File "C:\Users\Vaishnav\.virtualenvs\Tortoise-BOT-NdGTmAqy\lib\site-packages\discord\client.py", line 312, in _run_event
    await coro(*args, **kwargs)
  File "C:\Users\Vaishnav\Projects\Tortoise-BOT\bot\bot.py", line 43, in on_ready
    await self.on_first_ready()
  File "C:\Users\Vaishnav\Projects\Tortoise-BOT\bot\bot.py", line 49, in on_first_ready
    await self.reload_tortoise_meta_cache()
  File "C:\Users\Vaishnav\Projects\Tortoise-BOT\bot\bot.py", line 55, in reload_tortoise_meta_cache
    self.tortoise_meta_cache = await self.api_client.get_server_meta()
  File "C:\Users\Vaishnav\Projects\Tortoise-BOT\bot\api_client.py", line 128, in get_server_meta
    return await self.get(f"server/meta/{guild_id}/")
  File "C:\Users\Vaishnav\Projects\Tortoise-BOT\bot\api_client.py", line 62, in get
    await self.raise_for_status(resp)
  File "C:\Users\Vaishnav\Projects\Tortoise-BOT\bot\api_client.py", line 55, in raise_for_status
    raise ResponseCodeError(response=response, response_json=response_json)
bot.api_client.ResponseCodeError: Status: 401 Response: {'detail': 'Invalid token.'}

During handling of the above exception, another exception occurred:

Traceback (most recent call last):
  File "C:\Users\Vaishnav\.virtualenvs\Tortoise-BOT-NdGTmAqy\lib\site-packages\discord\client.py", line 317, in _run_event
    await self.on_error(event_name, *args, **kwargs)
  File "C:\Users\Vaishnav\Projects\Tortoise-BOT\bot\bot.py", line 90, in on_error
    await self.log_error(msg)
  File "C:\Users\Vaishnav\Projects\Tortoise-BOT\bot\bot.py", line 101, in log_error
    await error_log_channel.send(f"```Num {count+1}/{len(split_messages)}:\n{message}```")
  File "C:\Users\Vaishnav\.virtualenvs\Tortoise-BOT-NdGTmAqy\lib\site-packages\discord\abc.py", line 870, in send
    data = await state.http.send_message(channel.id, content, tts=tts, embed=embed, nonce=nonce)
  File "C:\Users\Vaishnav\.virtualenvs\Tortoise-BOT-NdGTmAqy\lib\site-packages\discord\http.py", line 221, in request
    raise Forbidden(r, data)
discord.errors.Forbidden: 403 Forbidden (error code: 50001): Missing Access
2020-09-17 00:23:46,349 - discord.client - Received signal to terminate bot and event loop.
2020-09-17 00:23:46,349 - discord.client - Cleaning up tasks.
2020-09-17 00:23:46,349 - discord.client - Cleaning up after 4 tasks.
2020-09-17 00:23:46,516 - discord.client - Closing the event loop.
